Workbook

Sheet FRETE MÁQUINAS
A1: STATUS | B1: FRETE | C1: HR | D1: KM | E1: R$ PROP | F1: R$ TERC | G1: CHASSI | H1: PREVISÃO | I1: REAL | J1: NOTA | K1: SOLICITANTE | L1: ESTÁ: | M1: VAI: | N1: TIPO | O1: ESTÁ EM: | P1: VAI PARA: | Q1: OBS
A2: CONCLUIDO | B2: TERCEIRO DEMETRIO | C2: 0.11944444 | D2: 115 | E2: =IFERROR((D2*7),"?") -> 805 | F2: 300 | G2: 1BM5080EEP4112594 | H2: 45964 | I2: 45964 | J2: CLIENTE → MANUTENÇÃO | K2: daisy.kakol | L2: CLIENTE | M2: IRATI | N2: DE CLIENTE PARA LOJA | O2: https://maps.app.goo.gl/MTXwpjxVEM4SBPA46 | P2: MPA | Q2: jose | R2: =IF( OR( IFERROR(FIND("BM",G2),0)>0, IFERROR(FIND("PY",G2),0)>0 ), MID(TRIM(SUBSTITUTE(SUBSTITUTE(G2,CHAR(160),""),CHAR(9),"")),4,5), MID(TRIM(SUBSTITUTE(SUBSTITUTE(G2,CHAR(160),""),CHAR(9),"")),4,4) ) -> 5080E | S2: {=_xlfn.LET( _xlpm.ch, TRIM(SUBSTITUTE(G2,CHAR(160),"")), _xlpm.ehTrator, OR(IFERROR(FIND("BM",_xlpm.ch),0)>0, IFERROR(FIND("PY",_xlpm.ch),0)>0), _xlpm.chave, IF(_xlpm.ehTrator, MID(_xlpm.ch,4,5), MID(_xlpm.ch,4,4)), _xlpm.fonte, IF(LEN(_xlpm.chave)=5, UTIL!BV:BV, UTIL!BU:BU), _xlpm.modelo, TRIM(SUBSTITUTE(R2,CHAR(160),"")), _xlpm.nomeMod, IFERROR(_xlfn.XLOOKUP("*"&_xlpm.modelo&"*", UTIL!D:D, UTIL!B:B, "", 2), IFERROR(_xlfn.XLOOKUP("*"&_xlpm.modelo&"*", UTIL!E:E, UTIL!B:B, "", 2), "")), _xlpm.tipoMod, IF(_xlpm.nomeMod="", "", IFERROR(LEFT(_xlpm.nomeMod, FIND(" ", _xlpm.nomeMod)-1), _xlpm.nomeMod)), _xlpm.dimMod, IFERROR(_xlfn.XLOOKUP("*"&_xlpm.modelo&"*", UTIL!D:D, UTIL!K:K, "", 2), IFERROR(_xlfn.XLOOKUP("*"&_xlpm.modelo&"*", UTIL!E:E, UTIL!K:K, "", 2), "")), _xlpm.tipotxt_antigo, IF(_xlpm.ehTrator, "TRATOR", IFERROR(_xlfn.XLOOKUP(_xlpm.chave, _xlpm.fonte, UTIL!BS:BS, "", 0), IFERROR(_xlfn.XLOOKUP("*"&_xlpm.chave&"*", _xlpm.fonte, UTIL!BS:BS, "", 2), "Não encontrado"))), _xlpm.dimtxt_antigo, IFERROR(_xlfn.XLOOKUP(_xlpm.chave, _xlpm.fonte, UTIL!CB:CB, "", 0), IFERROR(_xlfn.XLOOKUP("*"&_xlpm.chave&"*", _xlpm.fonte, UTIL!CB:CB, "", 2), "Não encontrado")), _xlpm.tipotxt, IF(_xlpm.tipoMod<>"", _xlpm.tipoMod, _xlpm.tipotxt_antigo), _xlpm.dimtxt, IF(_xlpm.dimMod<>"", _xlpm.dimMod, _xlpm.dimtxt_antigo), _xlpm.deTxt, IF(L2="CLIENTE", O2, IF(LEFT(L2,4)="http", L2, "MACPONTA AGRO DE "&L2)), _xlpm.paraBase, IF(M2="CLIENTE", P2, M2), _xlpm.paraTxt, IF(LEFT(_xlpm.paraBase,4)="http", _xlpm.paraBase, "MACPONTA AGRO DE "&_xlpm.paraBase), _xlpm.nfParte, IF(LEN(TRIM(I2))=0, "", " -NF "&TRIM(I2)), "- " & _xlpm.tipotxt & ": *" & G2 & "*" & CHAR(13)&CHAR(10) & "- " & _xlpm.dimtxt & CHAR(13)&CHAR(10) & "- *Cliente*: " & J2 & _xlpm.nfParte & CHAR(13)&CHAR(10) & "- *Obs:* " & Q2 & CHAR(13)&CHAR(10) & CHAR(10) & "- *De*: " & _xlpm.deTxt & CHAR(13)&CHAR(10) & "- *Para*: " & _xlpm.paraTxt & CHAR(13)&CHAR(10) & "- *Ida e volta*: +/- " & TEXT(((D2*1.5)/1440),"h:mm") & "h | " & D2 & "km" )} -> - TRATOR: *1BM5080EEP4112594*_x000D_ - _x000D_ - *Cliente*: CLIENTE → MANUTENÇÃO -NF 45964_x000D_ - *Obs:* jose_x000D_ - *De*: https://maps.app.goo.gl/MTXwpjxVEM4SBPA46_x000D_ - *Para*: MACPONTA AGRO DE IRATI_x000D_ - *Ida e volta*: +/- 2:52h | 115km
A3: CONCLUIDO | B3: TERCEIRO DEMETRIO | C3: 0.11944444 | D3: 115 | E3: =IFERROR((D3*7),"?") -> 805 | F3: 500 | G3: 1BM5080ECP4111950 | H3: 45964 | I3: 45964 | J3: MANUTENÇÃO → CLIENTE | K3: daisy.kakol | L3: IRATI | M3: CLIENTE | N3: DE LOJA PARA CLIENTE | O3: MPA | P3: https://maps.app.goo.gl/rYQLkSMERduCoffL8 | Q3: RICARDO DRANKA | R3: =IF( OR( IFERROR(FIND("BM",G3),0)>0, IFERROR(FIND("PY",G3),0)>0 ), MID(TRIM(SUBSTITUTE(SUBSTITUTE(G3,CHAR(160),""),CHAR(9),"")),4,5), MID(TRIM(SUBSTITUTE(SUBSTITUTE(G3,CHAR(160),""),CHAR(9),"")),4,4) ) -> 5080E | S3: {=_xlfn.LET( _xlpm.ch, TRIM(SUBSTITUTE(G3,CHAR(160),"")), _xlpm.ehTrator, OR(IFERROR(FIND("BM",_xlpm.ch),0)>0, IFERROR(FIND("PY",_xlpm.ch),0)>0), _xlpm.chave, IF(_xlpm.ehTrator, MID(_xlpm.ch,4,5), MID(_xlpm.ch,4,4)), _xlpm.fonte, IF(LEN(_xlpm.chave)=5, UTIL!BV:BV, UTIL!BU:BU), _xlpm.modelo, TRIM(SUBSTITUTE(R3,CHAR(160),"")), _xlpm.nomeMod, IFERROR(_xlfn.XLOOKUP("*"&_xlpm.modelo&"*", UTIL!D:D, UTIL!B:B, "", 2), IFERROR(_xlfn.XLOOKUP("*"&_xlpm.modelo&"*", UTIL!E:E, UTIL!B:B, "", 2), "")), _xlpm.tipoMod, IF(_xlpm.nomeMod="", "", IFERROR(LEFT(_xlpm.nomeMod, FIND(" ", _xlpm.nomeMod)-1), _xlpm.nomeMod)), _xlpm.dimMod, IFERROR(_xlfn.XLOOKUP("*"&_xlpm.modelo&"*", UTIL!D:D, UTIL!K:K, "", 2), IFERROR(_xlfn.XLOOKUP("*"&_xlpm.modelo&"*", UTIL!E:E, UTIL!K:K, "", 2), "")), _xlpm.tipotxt_antigo, IF(_xlpm.ehTrator, "TRATOR", IFERROR(_xlfn.XLOOKUP(_xlpm.chave, _xlpm.fonte, UTIL!BS:BS, "", 0), IFERROR(_xlfn.XLOOKUP("*"&_xlpm.chave&"*", _xlpm.fonte, UTIL!BS:BS, "", 2), "Não encontrado"))), _xlpm.dimtxt_antigo, IFERROR(_xlfn.XLOOKUP(_xlpm.chave, _xlpm.fonte, UTIL!CB:CB, "", 0), IFERROR(_xlfn.XLOOKUP("*"&_xlpm.chave&"*", _xlpm.fonte, UTIL!CB:CB, "", 2), "Não encontrado")), _xlpm.tipotxt, IF(_xlpm.tipoMod<>"", _xlpm.tipoMod, _xlpm.tipotxt_antigo), _xlpm.dimtxt, IF(_xlpm.dimMod<>"", _xlpm.dimMod, _xlpm.dimtxt_antigo), _xlpm.deTxt, IF(L3="CLIENTE", O3, IF(LEFT(L3,4)="http", L3, "MACPONTA AGRO DE "&L3)), _xlpm.paraBase, IF(M3="CLIENTE", P3, M3), _xlpm.paraTxt, IF(LEFT(_xlpm.paraBase,4)="http", _xlpm.paraBase, "MACPONTA AGRO DE "&_xlpm.paraBase), _xlpm.nfParte, IF(LEN(TRIM(I3))=0, "", " -NF "&TRIM(I3)), "- " & _xlpm.tipotxt & ": *" & G3 & "*" & CHAR(13)&CHAR(10) & "- " & _xlpm.dimtxt & CHAR(13)&CHAR(10) & "- *Cliente*: " & J3 & _xlpm.nfParte & CHAR(13)&CHAR(10) & "- *Obs:* " & Q3 & CHAR(13)&CHAR(10) & CHAR(10) & "- *De*: " & _xlpm.deTxt & CHAR(13)&CHAR(10) & "- *Para*: " & _xlpm.paraTxt & CHAR(13)&CHAR(10) & "- *Ida e volta*: +/- " & TEXT(((D3*1.5)/1440),"h:mm") & "h | " & D3 & "km" )} -> - TRATOR: *1BM5080ECP4111950*_x000D_ - _x000D_ - *Cliente*: MANUTENÇÃO → CLIENTE -NF 45964_x000D_ - *Obs:* RICARDO DRANKA_x000D_ - *De*: MACPONTA AGRO DE IRATI_x000D_ - *Para*: https://maps.app.goo.gl/rYQLkSMERduCoffL8_x000D_ - *Ida e volta*: +/- 2:52h | 115km
A4: CONCLUIDO | B4: TERCEIRO DEMETRIO | C4: 0.10208333 | D4: 98 | E4: =IFERROR((D4*7),"?") -> 686 | F4: 300 | G4: 1BM5060ECN4103629 | H4: 45964 | I4: 45964 | J4: MANUTENÇÃO → CLIENTE | K4: daisy.kakol | L4: IRATI | M4: CLIENTE | N4: DE LOJA PARA CLIENTE | O4: MPA | P4: https://maps.app.goo.gl/MLVchYQrLvQGhWWp6 | Q4: cezar | R4: =IF( OR( IFERROR(FIND("BM",G4),0)>0, IFERROR(FIND("PY",G4),0)>0 ), MID(TRIM(SUBSTITUTE(SUBSTITUTE(G4,CHAR(160),""),CHAR(9),"")),4,5), MID(TRIM(SUBSTITUTE(SUBSTITUTE(G4,CHAR(160),""),CHAR(9),"")),4,4) ) -> 5060E | S4: {=_xlfn.LET( _xlpm.ch, TRIM(SUBSTITUTE(G4,CHAR(160),"")), _xlpm.ehTrator, OR(IFERROR(FIND("BM",_xlpm.ch),0)>0, IFERROR(FIND("PY",_xlpm.ch),0)>0), _xlpm.chave, IF(_xlpm.ehTrator, MID(_xlpm.ch,4,5), MID(_xlpm.ch,4,4)), _xlpm.fonte, IF(LEN(_xlpm.chave)=5, UTIL!BV:BV, UTIL!BU:BU), _xlpm.modelo, TRIM(SUBSTITUTE(R4,CHAR(160),"")), _xlpm.nomeMod, IFERROR(_xlfn.XLOOKUP("*"&_xlpm.modelo&"*", UTIL!D:D, UTIL!B:B, "", 2), IFERROR(_xlfn.XLOOKUP("*"&_xlpm.modelo&"*", UTIL!E:E, UTIL!B:B, "", 2), "")), _xlpm.tipoMod, IF(_xlpm.nomeMod="", "", IFERROR(LEFT(_xlpm.nomeMod, FIND(" ", _xlpm.nomeMod)-1), _xlpm.nomeMod)), _xlpm.dimMod, IFERROR(_xlfn.XLOOKUP("*"&_xlpm.modelo&"*", UTIL!D:D, UTIL!K:K, "", 2), IFERROR(_xlfn.XLOOKUP("*"&_xlpm.modelo&"*", UTIL!E:E, UTIL!K:K, "", 2), "")), _xlpm.tipotxt_antigo, IF(_xlpm.ehTrator, "TRATOR", IFERROR(_xlfn.XLOOKUP(_xlpm.chave, _xlpm.fonte, UTIL!BS:BS, "", 0), IFERROR(_xlfn.XLOOKUP("*"&_xlpm.chave&"*", _xlpm.fonte, UTIL!BS:BS, "", 2), "Não encontrado"))), _xlpm.dimtxt_antigo, IFERROR(_xlfn.XLOOKUP(_xlpm.chave, _xlpm.fonte, UTIL!CB:CB, "", 0), IFERROR(_xlfn.XLOOKUP("*"&_xlpm.chave&"*", _xlpm.fonte, UTIL!CB:CB, "", 2), "Não encontrado")), _xlpm.tipotxt, IF(_xlpm.tipoMod<>"", _xlpm.tipoMod, _xlpm.tipotxt_antigo), _xlpm.dimtxt, IF(_xlpm.dimMod<>"", _xlpm.dimMod, _xlpm.dimtxt_antigo), _xlpm.deTxt, IF(L4="CLIENTE", O4, IF(LEFT(L4,4)="http", L4, "MACPONTA AGRO DE "&L4)), _xlpm.paraBase, IF(M4="CLIENTE", P4, M4), _xlpm.paraTxt, IF(LEFT(_xlpm.paraBase,4)="http", _xlpm.paraBase, "MACPONTA AGRO DE "&_xlpm.paraBase), _xlpm.nfParte, IF(LEN(TRIM(I4))=0, "", " -NF "&TRIM(I4)), "- " & _xlpm.tipotxt & ": *" & G4 & "*" & CHAR(13)&CHAR(10) & "- " & _xlpm.dimtxt & CHAR(13)&CHAR(10) & "- *Cliente*: " & J4 & _xlpm.nfParte & CHAR(13)&CHAR(10) & "- *Obs:* " & Q4 & CHAR(13)&CHAR(10) & CHAR(10) & "- *De*: " & _xlpm.deTxt & CHAR(13)&CHAR(10) & "- *Para*: " & _xlpm.paraTxt & CHAR(13)&CHAR(10) & "- *Ida e volta*: +/- " & TEXT(((D4*1.5)/1440),"h:mm") & "h | " & D4 & "km" )} -> - TRATOR: *1BM5060ECN4103629*_x000D_ - _x000D_ - *Cliente*: MANUTENÇÃO → CLIENTE -NF 45964_x000D_ - *Obs:* cezar_x000D_ - *De*: MACPONTA AGRO DE IRATI_x000D_ - *Para*: https://maps.app.goo.gl/MLVchYQrLvQGhWWp6_x000D_ - *Ida e volta*: +/- 2:27h | 98km
A5: CONCLUIDO | B5: TERCEIRO MAZETTO | C5: 0.17916667 | D5: 172 | E5: =IFERROR((D5*7),"?") -> 1204 | F5: 750 | G5: 1CQS760ACS0160134 | H5: 45964 | I5: 45964 | J5: ARNALDO STOCK -NF107847 | K5: euclides.junior | L5: GUARAPUAVA | M5: CLIENTE | N5: DE LOJA PARA CLIENTE | O5: MPA | P5: https://maps.app.goo.gl/Kk5FKYUBPHUbo26P8 | Q5: Fabio | R5: =IF( OR( IFERROR(FIND("BM",G5),0)>0, IFERROR(FIND("PY",G5),0)>0 ), MID(TRIM(SUBSTITUTE(SUBSTITUTE(G5,CHAR(160),""),CHAR(9),"")),4,5), MID(TRIM(SUBSTITUTE(SUBSTITUTE(G5,CHAR(160),""),CHAR(9),"")),4,4) ) -> S760 | S5: {=_xlfn.LET( _xlpm.ch, TRIM(SUBSTITUTE(G5,CHAR(160),"")), _xlpm.ehTrator, OR(IFERROR(FIND("BM",_xlpm.ch),0)>0, IFERROR(FIND("PY",_xlpm.ch),0)>0), _xlpm.chave, IF(_xlpm.ehTrator, MID(_xlpm.ch,4,5), MID(_xlpm.ch,4,4)), _xlpm.fonte, IF(LEN(_xlpm.chave)=5, UTIL!BV:BV, UTIL!BU:BU), _xlpm.modelo, TRIM(SUBSTITUTE(R5,CHAR(160),"")), _xlpm.nomeMod, IFERROR(_xlfn.XLOOKUP("*"&_xlpm.modelo&"*", UTIL!D:D, UTIL!B:B, "", 2), IFERROR(_xlfn.XLOOKUP("*"&_xlpm.modelo&"*", UTIL!E:E, UTIL!B:B, "", 2), "")), _xlpm.tipoMod, IF(_xlpm.nomeMod="", "", IFERROR(LEFT(_xlpm.nomeMod, FIND(" ", _xlpm.nomeMod)-1), _xlpm.nomeMod)), _xlpm.dimMod, IFERROR(_xlfn.XLOOKUP("*"&_xlpm.modelo&"*", UTIL!D:D, UTIL!K:K, "", 2), IFERROR(_xlfn.XLOOKUP("*"&_xlpm.modelo&"*", UTIL!E:E, UTIL!K:K, "", 2), "")), _xlpm.tipotxt_antigo, IF(_xlpm.ehTrator, "TRATOR", IFERROR(_xlfn.XLOOKUP(_xlpm.chave, _xlpm.fonte, UTIL!BS:BS, "", 0), IFERROR(_xlfn.XLOOKUP("*"&_xlpm.chave&"*", _xlpm.fonte, UTIL!BS:BS, "", 2), "Não encontrado"))), _xlpm.dimtxt_antigo, IFERROR(_xlfn.XLOOKUP(_xlpm.chave, _xlpm.fonte, UTIL!CB:CB, "", 0), IFERROR(_xlfn.XLOOKUP("*"&_xlpm.chave&"*", _xlpm.fonte, UTIL!CB:CB, "", 2), "Não encontrado")), _xlpm.tipotxt, IF(_xlpm.tipoMod<>"", _xlpm.tipoMod, _xlpm.tipotxt_antigo), _xlpm.dimtxt, IF(_xlpm.dimMod<>"", _xlpm.dimMod, _xlpm.dimtxt_antigo), _xlpm.deTxt, IF(L5="CLIENTE", O5, IF(LEFT(L5,4)="http", L5, "MACPONTA AGRO DE "&L5)), _xlpm.paraBase, IF(M5="CLIENTE", P5, M5), _xlpm.paraTxt, IF(LEFT(_xlpm.paraBase,4)="http", _xlpm.paraBase, "MACPONTA AGRO DE "&_xlpm.paraBase), _xlpm.nfParte, IF(LEN(TRIM(I5))=0, "", " -NF "&TRIM(I5)), "- " & _xlpm.tipotxt & ": *" & G5 & "*" & CHAR(13)&CHAR(10) & "- " & _xlpm.dimtxt & CHAR(13)&CHAR(10) & "- *Cliente*: " & J5 & _xlpm.nfParte & CHAR(13)&CHAR(10) & "- *Obs:* " & Q5 & CHAR(13)&CHAR(10) & CHAR(10) & "- *De*: " & _xlpm.deTxt & CHAR(13)&CHAR(10) & "- *Para*: " & _xlpm.paraTxt & CHAR(13)&CHAR(10) & "- *Ida e volta*: +/- " & TEXT(((D5*1.5)/1440),"h:mm") & "h | " & D5 & "km" )} -> - COLHEITADEIRA: *1CQS760ACS0160134*_x000D_ - A:4,00 x C:10,60 x L:3,50-5,20 x P:18.599kg_x000D_ - *Cliente*: ARNALDO STOCK -NF107847 -NF 45964_x000D_ - *Obs:* Fabio _x000D_ - *De*: MACPONTA AGRO DE GUARAPUAVA_x000D_ - *Para*: https://maps.app.goo.gl/Kk5FKYUBPHUbo26P8_x000D_ - *Ida e volta*: +/- 4:18h | 172km
A6: CONCLUIDO | B6: TERCEIRO MAZETTO | C6: 0.17916667 | D6: 172 | E6: =IFERROR((D6*7),"?") -> 1204 | F6: 750 | G6: 1CQFA30AAS0160114 | H6: 45964 | I6: 45964 | J6: ARNALDO STOCK -NF107847 | K6: euclides.junior | L6: GUARAPUAVA | M6: CLIENTE | N6: DE LOJA PARA CLIENTE | O6: MPA | P6: https://maps.app.goo.gl/kFwUPivsMpYS8pGd8 | Q6: Fabio | R6: =IF( OR( IFERROR(FIND("BM",G6),0)>0, IFERROR(FIND("PY",G6),0)>0 ), MID(TRIM(SUBSTITUTE(SUBSTITUTE(G6,CHAR(160),""),CHAR(9),"")),4,5), MID(TRIM(SUBSTITUTE(SUBSTITUTE(G6,CHAR(160),""),CHAR(9),"")),4,4) ) -> FA30 | S6: {=_xlfn.LET( _xlpm.ch, TRIM(SUBSTITUTE(G6,CHAR(160),"")), _xlpm.ehTrator, OR(IFERROR(FIND("BM",_xlpm.ch),0)>0, IFERROR(FIND("PY",_xlpm.ch),0)>0), _xlpm.chave, IF(_xlpm.ehTrator, MID(_xlpm.ch,4,5), MID(_xlpm.ch,4,4)), _xlpm.fonte, IF(LEN(_xlpm.chave)=5, UTIL!BV:BV, UTIL!BU:BU), _xlpm.modelo, TRIM(SUBSTITUTE(R6,CHAR(160),"")), _xlpm.nomeMod, IFERROR(_xlfn.XLOOKUP("*"&_xlpm.modelo&"*", UTIL!D:D, UTIL!B:B, "", 2), IFERROR(_xlfn.XLOOKUP("*"&_xlpm.modelo&"*", UTIL!E:E, UTIL!B:B, "", 2), "")), _xlpm.tipoMod, IF(_xlpm.nomeMod="", "", IFERROR(LEFT(_xlpm.nomeMod, FIND(" ", _xlpm.nomeMod)-1), _xlpm.nomeMod)), _xlpm.dimMod, IFERROR(_xlfn.XLOOKUP("*"&_xlpm.modelo&"*", UTIL!D:D, UTIL!K:K, "", 2), IFERROR(_xlfn.XLOOKUP("*"&_xlpm.modelo&"*", UTIL!E:E, UTIL!K:K, "", 2), "")), _xlpm.tipotxt_antigo, IF(_xlpm.ehTrator, "TRATOR", IFERROR(_xlfn.XLOOKUP(_xlpm.chave, _xlpm.fonte, UTIL!BS:BS, "", 0), IFERROR(_xlfn.XLOOKUP("*"&_xlpm.chave&"*", _xlpm.fonte, UTIL!BS:BS, "", 2), "Não encontrado"))), _xlpm.dimtxt_antigo, IFERROR(_xlfn.XLOOKUP(_xlpm.chave, _xlpm.fonte, UTIL!CB:CB, "", 0), IFERROR(_xlfn.XLOOKUP("*"&_xlpm.chave&"*", _xlpm.fonte, UTIL!CB:CB, "", 2), "Não encontrado")), _xlpm.tipotxt, IF(_xlpm.tipoMod<>"", _xlpm.tipoMod, _xlpm.tipotxt_antigo), _xlpm.dimtxt, IF(_xlpm.dimMod<>"", _xlpm.dimMod, _xlpm.dimtxt_antigo), _xlpm.deTxt, IF(L6="CLIENTE", O6, IF(LEFT(L6,4)="http", L6, "MACPONTA AGRO DE "&L6)), _xlpm.paraBase, IF(M6="CLIENTE", P6, M6), _xlpm.paraTxt, IF(LEFT(_xlpm.paraBase,4)="http", _xlpm.paraBase, "MACPONTA AGRO DE "&_xlpm.paraBase), _xlpm.nfParte, IF(LEN(TRIM(I6))=0, "", " -NF "&TRIM(I6)), "- " & _xlpm.tipotxt & ": *" & G6 & "*" & CHAR(13)&CHAR(10) & "- " & _xlpm.dimtxt & CHAR(13)&CHAR(10) & "- *Cliente*: " & J6 & _xlpm.nfParte & CHAR(13)&CHAR(10) & "- *Obs:* " & Q6 & CHAR(13)&CHAR(10) & CHAR(10) & "- *De*: " & _xlpm.deTxt & CHAR(13)&CHAR(10) & "- *Para*: " & _xlpm.paraTxt & CHAR(13)&CHAR(10) & "- *Ida e volta*: +/- " & TEXT(((D6*1.5)/1440),"h:mm") & "h | " & D6 & "km" )} -> - PLATAFORMA: *1CQFA30AAS0160114*_x000D_ - A:1,60 x C:9,14 x L:1,80-1,80 x P:2.900kg_x000D_ - *Cliente*: ARNALDO STOCK -NF107847 -NF 45964_x000D_ - *Obs:* Fabio _x000D_ - *De*: MACPONTA AGRO DE GUARAPUAVA_x000D_ - *Para*: https://maps.app.goo.gl/kFwUPivsMpYS8pGd8_x000D_ - *Ida e volta*: +/- 4:18h | 172km
A7: CONCLUIDO | B7: TERCEIRO MAZETTO | C7: 0.15625 | D7: 150 | E7: =IFERROR((D7*7),"?") -> 1050 | F7: 1352 | G7: 1BM5080EPS4204124 | H7: 45964 | I7: 45964 | J7: LUIZ HENRIQUE GREIN -NF107347 | K7: euclides.junior | L7: GUARAPUAVA | M7: CLIENTE | N7: DE LOJA PARA CLIENTE | O7: MPA | P7: https://maps.app.goo.gl/jZEWqzLvNcpTnRBE8 | Q7: Emerson | R7: =IF( OR( IFERROR(FIND("BM",G7),0)>0, IFERROR(FIND("PY",G7),0)>0 ), MID(TRIM(SUBSTITUTE(SUBSTITUTE(G7,CHAR(160),""),CHAR(9),"")),4,5), MID(TRIM(SUBSTITUTE(SUBSTITUTE(G7,CHAR(160),""),CHAR(9),"")),4,4) ) -> 5080E | S7: {=_xlfn.LET( _xlpm.ch, TRIM(SUBSTITUTE(G7,CHAR(160),"")), _xlpm.ehTrator, OR(IFERROR(FIND("BM",_xlpm.ch),0)>0, IFERROR(FIND("PY",_xlpm.ch),0)>0), _xlpm.chave, IF(_xlpm.ehTrator, MID(_xlpm.ch,4,5), MID(_xlpm.ch,4,4)), _xlpm.fonte, IF(LEN(_xlpm.chave)=5, UTIL!BV:BV, UTIL!BU:BU), _xlpm.modelo, TRIM(SUBSTITUTE(R7,CHAR(160),"")), _xlpm.nomeMod, IFERROR(_xlfn.XLOOKUP("*"&_xlpm.modelo&"*", UTIL!D:D, UTIL!B:B, "", 2), IFERROR(_xlfn.XLOOKUP("*"&_xlpm.modelo&"*", UTIL!E:E, UTIL!B:B, "", 2), "")), _xlpm.tipoMod, IF(_xlpm.nomeMod="", "", IFERROR(LEFT(_xlpm.nomeMod, FIND(" ", _xlpm.nomeMod)-1), _xlpm.nomeMod)), _xlpm.dimMod, IFERROR(_xlfn.XLOOKUP("*"&_xlpm.modelo&"*", UTIL!D:D, UTIL!K:K, "", 2), IFERROR(_xlfn.XLOOKUP("*"&_xlpm.modelo&"*", UTIL!E:E, UTIL!K:K, "", 2), "")), _xlpm.tipotxt_antigo, IF(_xlpm.ehTrator, "TRATOR", IFERROR(_xlfn.XLOOKUP(_xlpm.chave, _xlpm.fonte, UTIL!BS:BS, "", 0), IFERROR(_xlfn.XLOOKUP("*"&_xlpm.chave&"*", _xlpm.fonte, UTIL!BS:BS, "", 2), "Não encontrado"))), _xlpm.dimtxt_antigo, IFERROR(_xlfn.XLOOKUP(_xlpm.chave, _xlpm.fonte, UTIL!CB:CB, "", 0), IFERROR(_xlfn.XLOOKUP("*"&_xlpm.chave&"*", _xlpm.fonte, UTIL!CB:CB, "", 2), "Não encontrado")), _xlpm.tipotxt, IF(_xlpm.tipoMod<>"", _xlpm.tipoMod, _xlpm.tipotxt_antigo), _xlpm.dimtxt, IF(_xlpm.dimMod<>"", _xlpm.dimMod, _xlpm.dimtxt_antigo), _xlpm.deTxt, IF(L7="CLIENTE", O7, IF(LEFT(L7,4)="http", L7, "MACPONTA AGRO DE "&L7)), _xlpm.paraBase, IF(M7="CLIENTE", P7, M7), _xlpm.paraTxt, IF(LEFT(_xlpm.paraBase,4)="http", _xlpm.paraBase, "MACPONTA AGRO DE "&_xlpm.paraBase), _xlpm.nfParte, IF(LEN(TRIM(I7))=0, "", " -NF "&TRIM(I7)), "- " & _xlpm.tipotxt & ": *" & G7 & "*" & CHAR(13)&CHAR(10) & "- " & _xlpm.dimtxt & CHAR(13)&CHAR(10) & "- *Cliente*: " & J7 & _xlpm.nfParte & CHAR(13)&CHAR(10) & "- *Obs:* " & Q7 & CHAR(13)&CHAR(10) & CHAR(10) & "- *De*: " & _xlpm.deTxt & CHAR(13)&CHAR(10) & "- *Para*: " & _xlpm.paraTxt & CHAR(13)&CHAR(10) & "- *Ida e volta*: +/- " & TEXT(((D7*1.5)/1440),"h:mm") & "h | " & D7 & "km" )} -> - TRATOR: *1BM5080EPS4204124*_x000D_ - _x000D_ - *Cliente*: LUIZ HENRIQUE GREIN -NF107347 -NF 45964_x000D_ - *Obs:* Emerson_x000D_ - *De*: MACPONTA AGRO DE GUARAPUAVA_x000D_ - *Para*: https://maps.app.goo.gl/jZEWqzLvNcpTnRBE8_x000D_ - *Ida e volta*: +/- 3:45h | 150km
A8: CONCLUIDO | B8: TERCEIRO STOSKI | C8: 0.072916667 | D8: 70 | E8: =IFERROR((D8*7),"?") -> 490 | F8: 910 | G8: 1BM6135MPSH000596 | H8: 45964 | I8: 45964 | J8: LAURO MIGUEL STRONA -NF76755 | K8: marcio.jacovossi | L8: IRATI | M8: CLIENTE | N8: DE LOJA PARA CLIENTE | O8: MPA | P8: https://maps.app.goo.gl/JxzGitfYRrvxzYUL9 | Q8: LAURO MIGUEL STRONA 42 999269190 | R8: =IF( OR( IFERROR(FIND("BM",G8),0)>0, IFERROR(FIND("PY",G8),0)>0 ), MID(TRIM(SUBSTITUTE(SUBSTITUTE(G8,CHAR(160),""),CHAR(9),"")),4,5), MID(TRIM(SUBSTITUTE(SUBSTITUTE(G8,CHAR(160),""),CHAR(9),"")),4,4) ) -> 6135M | S8: {=_xlfn.LET( _xlpm.ch, TRIM(SUBSTITUTE(G8,CHAR(160),"")), _xlpm.ehTrator, OR(IFERROR(FIND("BM",_xlpm.ch),0)>0, IFERROR(FIND("PY",_xlpm.ch),0)>0), _xlpm.chave, IF(_xlpm.ehTrator, MID(_xlpm.ch,4,5), MID(_xlpm.ch,4,4)), _xlpm.fonte, IF(LEN(_xlpm.chave)=5, UTIL!BV:BV, UTIL!BU:BU), _xlpm.modelo, TRIM(SUBSTITUTE(R8,CHAR(160),"")), _xlpm.nomeMod, IFERROR(_xlfn.XLOOKUP("*"&_xlpm.modelo&"*", UTIL!D:D, UTIL!B:B, "", 2), IFERROR(_xlfn.XLOOKUP("*"&_xlpm.modelo&"*", UTIL!E:E, UTIL!B:B, "", 2), "")), _xlpm.tipoMod, IF(_xlpm.nomeMod="", "", IFERROR(LEFT(_xlpm.nomeMod, FIND(" ", _xlpm.nomeMod)-1), _xlpm.nomeMod)), _xlpm.dimMod, IFERROR(_xlfn.XLOOKUP("*"&_xlpm.modelo&"*", UTIL!D:D, UTIL!K:K, "", 2), IFERROR(_xlfn.XLOOKUP("*"&_xlpm.modelo&"*", UTIL!E:E, UTIL!K:K, "", 2), "")), _xlpm.tipotxt_antigo, IF(_xlpm.ehTrator, "TRATOR", IFERROR(_xlfn.XLOOKUP(_xlpm.chave, _xlpm.fonte, UTIL!BS:BS, "", 0), IFERROR(_xlfn.XLOOKUP("*"&_xlpm.chave&"*", _xlpm.fonte, UTIL!BS:BS, "", 2), "Não encontrado"))), _xlpm.dimtxt_antigo, IFERROR(_xlfn.XLOOKUP(_xlpm.chave, _xlpm.fonte, UTIL!CB:CB, "", 0), IFERROR(_xlfn.XLOOKUP("*"&_xlpm.chave&"*", _xlpm.fonte, UTIL!CB:CB, "", 2), "Não encontrado")), _xlpm.tipotxt, IF(_xlpm.tipoMod<>"", _xlpm.tipoMod, _xlpm.tipotxt_antigo), _xlpm.dimtxt, IF(_xlpm.dimMod<>"", _xlpm.dimMod, _xlpm.dimtxt_antigo), _xlpm.deTxt, IF(L8="CLIENTE", O8, IF(LEFT(L8,4)="http", L8, "MACPONTA AGRO DE "&L8)), _xlpm.paraBase, IF(M8="CLIENTE", P8, M8), _xlpm.paraTxt, IF(LEFT(_xlpm.paraBase,4)="http", _xlpm.paraBase, "MACPONTA AGRO DE "&_xlpm.paraBase), _xlpm.nfParte, IF(LEN(TRIM(I8))=0, "", " -NF "&TRIM(I8)), "- " & _xlpm.tipotxt & ": *" & G8 & "*" & CHAR(13)&CHAR(10) & "- " & _xlpm.dimtxt & CHAR(13)&CHAR(10) & "- *Cliente*: " & J8 & _xlpm.nfParte & CHAR(13)&CHAR(10) & "- *Obs:* " & Q8 & CHAR(13)&CHAR(10) & CHAR(10) & "- *De*: " & _xlpm.deTxt & CHAR(13)&CHAR(10) & "- *Para*: " & _xlpm.paraTxt & CHAR(13)&CHAR(10) & "- *Ida e volta*: +/- " & TEXT(((D8*1.5)/1440),"h:mm") & "h | " & D8 & "km" )} -> - TRATOR: *1BM6135MPSH000596*_x000D_ - _x000D_ - *Cliente*: LAURO MIGUEL STRONA -NF76755 -NF 45964_x000D_ - *Obs:* LAURO MIGUEL STRONA 42 999269190_x000D_ - *De*: MACPONTA AGRO DE IRATI_x000D_ - *Para*: https://maps.app.goo.gl/JxzGitfYRrvxzYUL9_x000D_ - *Ida e volta*: +/- 1:45h | 70km
A9: CONCLUIDO | B9: PROPRIO VW | C9: 0.058333333 | D9: 56 | E9: =IFERROR((D9*7),"?") -> 392 | F9: 0 | G9: 1BM5060EES4201594 | H9: 45965 | I9: 45964 | J9: JOAQUIM MASCARENHAS -NF278279 | K9: marcos.ribas | L9: PONTA GROSSA | M9: CLIENTE | N9: DE LOJA PARA CLIENTE | O9: MPA | P9: https://maps.app.goo.gl/s5tPSxgcuWhSkcKc7 | Q9: PAULO - +55 42 9991-2229 - AVISAR ANGELO PARA ACOMPANHAR | R9: =IF( OR( IFERROR(FIND("BM",G9),0)>0, IFERROR(FIND("PY",G9),0)>0 ), MID(TRIM(SUBSTITUTE(SUBSTITUTE(G9,CHAR(160),""),CHAR(9),"")),4,5), MID(TRIM(SUBSTITUTE(SUBSTITUTE(G9,CHAR(160),""),CHAR(9),"")),4,4) ) -> 5060E | S9: {=_xlfn.LET( _xlpm.ch, TRIM(SUBSTITUTE(G9,CHAR(160),"")), _xlpm.ehTrator, OR(IFERROR(FIND("BM",_xlpm.ch),0)>0, IFERROR(FIND("PY",_xlpm.ch),0)>0), _xlpm.chave, IF(_xlpm.ehTrator, MID(_xlpm.ch,4,5), MID(_xlpm.ch,4,4)), _xlpm.fonte, IF(LEN(_xlpm.chave)=5, UTIL!BV:BV, UTIL!BU:BU), _xlpm.modelo, TRIM(SUBSTITUTE(R9,CHAR(160),"")), _xlpm.nomeMod, IFERROR(_xlfn.XLOOKUP("*"&_xlpm.modelo&"*", UTIL!D:D, UTIL!B:B, "", 2), IFERROR(_xlfn.XLOOKUP("*"&_xlpm.modelo&"*", UTIL!E:E, UTIL!B:B, "", 2), "")), _xlpm.tipoMod, IF(_xlpm.nomeMod="", "", IFERROR(LEFT(_xlpm.nomeMod, FIND(" ", _xlpm.nomeMod)-1), _xlpm.nomeMod)), _xlpm.dimMod, IFERROR(_xlfn.XLOOKUP("*"&_xlpm.modelo&"*", UTIL!D:D, UTIL!K:K, "", 2), IFERROR(_xlfn.XLOOKUP("*"&_xlpm.modelo&"*", UTIL!E:E, UTIL!K:K, "", 2), "")), _xlpm.tipotxt_antigo, IF(_xlpm.ehTrator, "TRATOR", IFERROR(_xlfn.XLOOKUP(_xlpm.chave, _xlpm.fonte, UTIL!BS:BS, "", 0), IFERROR(_xlfn.XLOOKUP("*"&_xlpm.chave&"*", _xlpm.fonte, UTIL!BS:BS, "", 2), "Não encontrado"))), _xlpm.dimtxt_antigo, IFERROR(_xlfn.XLOOKUP(_xlpm.chave, _xlpm.fonte, UTIL!CB:CB, "", 0), IFERROR(_xlfn.XLOOKUP("*"&_xlpm.chave&"*", _xlpm.fonte, UTIL!CB:CB, "", 2), "Não encontrado")), _xlpm.tipotxt, IF(_xlpm.tipoMod<>"", _xlpm.tipoMod, _xlpm.tipotxt_antigo), _xlpm.dimtxt, IF(_xlpm.dimMod<>"", _xlpm.dimMod, _xlpm.dimtxt_antigo), _xlpm.deTxt, IF(L9="CLIENTE", O9, IF(LEFT(L9,4)="http", L9, "MACPONTA AGRO DE "&L9)), _xlpm.paraBase, IF(M9="CLIENTE", P9, M9), _xlpm.paraTxt, IF(LEFT(_xlpm.paraBase,4)="http", _xlpm.paraBase, "MACPONTA AGRO DE "&_xlpm.paraBase), _xlpm.nfParte, IF(LEN(TRIM(I9))=0, "", " -NF "&TRIM(I9)), "- " & _xlpm.tipotxt & ": *" & G9 & "*" & CHAR(13)&CHAR(10) & "- " & _xlpm.dimtxt & CHAR(13)&CHAR(10) & "- *Cliente*: " & J9 & _xlpm.nfParte & CHAR(13)&CHAR(10) & "- *Obs:* " & Q9 & CHAR(13)&CHAR(10) & CHAR(10) & "- *De*: " & _xlpm.deTxt & CHAR(13)&CHAR(10) & "- *Para*: " & _xlpm.paraTxt & CHAR(13)&CHAR(10) & "- *Ida e volta*: +/- " & TEXT(((D9*1.5)/1440),"h:mm") & "h | " & D9 & "km" )} -> - TRATOR: *1BM5060EES4201594*_x000D_ - _x000D_ - *Cliente*: JOAQUIM MASCARENHAS -NF278279 -NF 45964_x000D_ - *Obs:* PAULO - +55 42 9991-2229 - AVISAR ANGELO PARA ACOMPANHAR_x000D_ - *De*: MACPONTA AGRO DE PONTA GROSSA_x000D_ - *Para*: https://maps.app.goo.gl/s5tPSxgcuWhSkcKc7_x000D_ - *Ida e volta*: +/- 1:24h | 56km
A10: CONCLUIDO | B10: PROPRIO VW | C10: 0.34375 | D10: 330 | E10: =IFERROR((D10*7),"?") -> 2310 | F10: 0 | G10: 1NW4025MVKF190132 | H10: 45965 | I10: 45965 | J10: MARLON BONILHA -NF61707 | K10: edenilson.mattos | L10: PONTA GROSSA | M10: CLIENTE | N10: DE LOJA PARA CLIENTE | O10: MPA | P10: Fazenda Irmãos II - Cidade Tomazina - PR | Q10: Contato CEN Alison 43.98409-2094 | R10: =IF( OR( IFERROR(FIND("BM",G10),0)>0, IFERROR(FIND("PY",G10),0)>0 ), MID(TRIM(SUBSTITUTE(SUBSTITUTE(G10,CHAR(160),""),CHAR(9),"")),4,5), MID(TRIM(SUBSTITUTE(SUBSTITUTE(G10,CHAR(160),""),CHAR(9),"")),4,4) ) -> 4025 | S10: {=_xlfn.LET( _xlpm.ch, TRIM(SUBSTITUTE(G10,CHAR(160),"")), _xlpm.ehTrator, OR(IFERROR(FIND("BM",_xlpm.ch),0)>0, IFERROR(FIND("PY",_xlpm.ch),0)>0), _xlpm.chave, IF(_xlpm.ehTrator, MID(_xlpm.ch,4,5), MID(_xlpm.ch,4,4)), _xlpm.fonte, IF(LEN(_xlpm.chave)=5, UTIL!BV:BV, UTIL!BU:BU), _xlpm.modelo, TRIM(SUBSTITUTE(R10,CHAR(160),"")), _xlpm.nomeMod, IFERROR(_xlfn.XLOOKUP("*"&_xlpm.modelo&"*", UTIL!D:D, UTIL!B:B, "", 2), IFERROR(_xlfn.XLOOKUP("*"&_xlpm.modelo&"*", UTIL!E:E, UTIL!B:B, "", 2), "")), _xlpm.tipoMod, IF(_xlpm.nomeMod="", "", IFERROR(LEFT(_xlpm.nomeMod, FIND(" ", _xlpm.nomeMod)-1), _xlpm.nomeMod)), _xlpm.dimMod, IFERROR(_xlfn.XLOOKUP("*"&_xlpm.modelo&"*", UTIL!D:D, UTIL!K:K, "", 2), IFERROR(_xlfn.XLOOKUP("*"&_xlpm.modelo&"*", UTIL!E:E, UTIL!K:K, "", 2), "")), _xlpm.tipotxt_antigo, IF(_xlpm.ehTrator, "TRATOR", IFERROR(_xlfn.XLOOKUP(_xlpm.chave, _xlpm.fonte, UTIL!BS:BS, "", 0), IFERROR(_xlfn.XLOOKUP("*"&_xlpm.chave&"*", _xlpm.fonte, UTIL!BS:BS, "", 2), "Não encontrado"))), _xlpm.dimtxt_antigo, IFERROR(_xlfn.XLOOKUP(_xlpm.chave, _xlpm.fonte, UTIL!CB:CB, "", 0), IFERROR(_xlfn.XLOOKUP("*"&_xlpm.chave&"*", _xlpm.fonte, UTIL!CB:CB, "", 2), "Não encontrado")), _xlpm.tipotxt, IF(_xlpm.tipoMod<>"", _xlpm.tipoMod, _xlpm.tipotxt_antigo), _xlpm.dimtxt, IF(_xlpm.dimMod<>"", _xlpm.dimMod, _xlpm.dimtxt_antigo), _xlpm.deTxt, IF(L10="CLIENTE", O10, IF(LEFT(L10,4)="http", L10, "MACPONTA AGRO DE "&L10)), _xlpm.paraBase, IF(M10="CLIENTE", P10, M10), _xlpm.paraTxt, IF(LEFT(_xlpm.paraBase,4)="http", _xlpm.paraBase, "MACPONTA AGRO DE "&_xlpm.paraBase), _xlpm.nfParte, IF(LEN(TRIM(I10))=0, "", " -NF "&TRIM(I10)), "- " & _xlpm.tipotxt & ": *" & G10 & "*" & CHAR(13)&CHAR(10) & "- " & _xlpm.dimtxt & CHAR(13)&CHAR(10) & "- *Cliente*: " & J10 & _xlpm.nfParte & CHAR(13)&CHAR(10) & "- *Obs:* " & Q10 & CHAR(13)&CHAR(10) & CHAR(10) & "- *De*: " & _xlpm.deTxt & CHAR(13)&CHAR(10) & "- *Para*: " & _xlpm.paraTxt & CHAR(13)&CHAR(10) & "- *Ida e volta*: +/- " & TEXT(((D10*1.5)/1440),"h:mm") & "h | " & D10 & "km" )} -> - PULVERIZADOR: *1NW4025MVKF190132*_x000D_ - A:3,34 x C:7,00 x L:2,72-3,30 x P:9.703kg_x000D_ - *Cliente*: MARLON BONILHA -NF61707 -NF 45965_x000D_ - *Obs:* Contato CEN Alison 43.98409-2094_x000D_ - *De*: MACPONTA AGRO DE PONTA GROSSA_x000D_ - *Para*: MACPONTA AGRO DE Fazenda Irmãos II - Cidade Tomazina - PR_x000D_ - *Ida e volta*: +/- 8:15h | 330km
A11: CONCLUIDO | B11: TERCEIRO NELSON | C11: 0.19236111 | D11: 185 | E11: =IFERROR((D11*7),"?") -> 1295 | F11: 1985 | G11: 1BM5060EAP4104558 | H11: 45965 | I11: 45965 | J11: MANUTENÇÃO → CLIENTE | K11: rafael.santos | L11: CLIENTE | M11: ARAPOTI | N11: DE CLIENTE PARA LOJA | O11: https://maps.app.goo.gl/PXTmMqoYPtx48Gex6 | P11: MPA | Q11: LUCIANO DE FREITAS - 43 99624-6946 | R11: =IF( OR( IFERROR(FIND("BM",G11),0)>0, IFERROR(FIND("PY",G11),0)>0 ), MID(TRIM(SUBSTITUTE(SUBSTITUTE(G11,CHAR(160),""),CHAR(9),"")),4,5), MID(TRIM(SUBSTITUTE(SUBSTITUTE(G11,CHAR(160),""),CHAR(9),"")),4,4) ) -> 5060E | S11: {=_xlfn.LET( _xlpm.ch, TRIM(SUBSTITUTE(G11,CHAR(160),"")), _xlpm.ehTrator, OR(IFERROR(FIND("BM",_xlpm.ch),0)>0, IFERROR(FIND("PY",_xlpm.ch),0)>0), _xlpm.chave, IF(_xlpm.ehTrator, MID(_xlpm.ch,4,5), MID(_xlpm.ch,4,4)), _xlpm.fonte, IF(LEN(_xlpm.chave)=5, UTIL!BV:BV, UTIL!BU:BU), _xlpm.modelo, TRIM(SUBSTITUTE(R11,CHAR(160),"")), _xlpm.nomeMod, IFERROR(_xlfn.XLOOKUP("*"&_xlpm.modelo&"*", UTIL!D:D, UTIL!B:B, "", 2), IFERROR(_xlfn.XLOOKUP("*"&_xlpm.modelo&"*", UTIL!E:E, UTIL!B:B, "", 2), "")), _xlpm.tipoMod, IF(_xlpm.nomeMod="", "", IFERROR(LEFT(_xlpm.nomeMod, FIND(" ", _xlpm.nomeMod)-1), _xlpm.nomeMod)), _xlpm.dimMod, IFERROR(_xlfn.XLOOKUP("*"&_xlpm.modelo&"*", UTIL!D:D, UTIL!K:K, "", 2), IFERROR(_xlfn.XLOOKUP("*"&_xlpm.modelo&"*", UTIL!E:E, UTIL!K:K, "", 2), "")), _xlpm.tipotxt_antigo, IF(_xlpm.ehTrator, "TRATOR", IFERROR(_xlfn.XLOOKUP(_xlpm.chave, _xlpm.fonte, UTIL!BS:BS, "", 0), IFERROR(_xlfn.XLOOKUP("*"&_xlpm.chave&"*", _xlpm.fonte, UTIL!BS:BS, "", 2), "Não encontrado"))), _xlpm.dimtxt_antigo, IFERROR(_xlfn.XLOOKUP(_xlpm.chave, _xlpm.fonte, UTIL!CB:CB, "", 0), IFERROR(_xlfn.XLOOKUP("*"&_xlpm.chave&"*", _xlpm.fonte, UTIL!CB:CB, "", 2), "Não encontrado")), _xlpm.tipotxt, IF(_xlpm.tipoMod<>"", _xlpm.tipoMod, _xlpm.tipotxt_antigo), _xlpm.dimtxt, IF(_xlpm.dimMod<>"", _xlpm.dimMod, _xlpm.dimtxt_antigo), _xlpm.deTxt, IF(L11="CLIENTE", O11, IF(LEFT(L11,4)="http", L11, "MACPONTA AGRO DE "&L11)), _xlpm.paraBase, IF(M11="CLIENTE", P11, M11), _xlpm.paraTxt, IF(LEFT(_xlpm.paraBase,4)="http", _xlpm.paraBase, "MACPONTA AGRO DE "&_xlpm.paraBase), _xlpm.nfParte, IF(LEN(TRIM(I11))=0, "", " -NF "&TRIM(I11)), "- " & _xlpm.tipotxt & ": *" & G11 & "*" & CHAR(13)&CHAR(10) & "- " & _xlpm.dimtxt & CHAR(13)&CHAR(10) & "- *Cliente*: " & J11 & _xlpm.nfParte & CHAR(13)&CHAR(10) & "- *Obs:* " & Q11 & CHAR(13)&CHAR(10) & CHAR(10) & "- *De*: " & _xlpm.deTxt & CHAR(13)&CHAR(10) & "- *Para*: " & _xlpm.paraTxt & CHAR(13)&CHAR(10) & "- *Ida e volta*: +/- " & TEXT(((D11*1.5)/1440),"h:mm") & "h | " & D11 & "km" )} -> - TRATOR: *1BM5060EAP4104558*_x000D_ - _x000D_ - *Cliente*: MANUTENÇÃO → CLIENTE -NF 45965_x000D_ - *Obs:* LUCIANO DE FREITAS - 43 99624-6946_x000D_ - *De*: https://maps.app.goo.gl/PXTmMqoYPtx48Gex6_x000D_ - *Para*: MACPONTA AGRO DE ARAPOTI_x000D_ - *Ida e volta*: +/- 4:37h | 185km
A12: CONCLUIDO | B12: PROPRIO DAF | C12: 0.052777778 | D12: 51 | E12: =IFERROR((D12*7),"?") -> 357 | F12: 0 | G12: 1BM7215CVR3000057 | H12: 45966 | I12: 45967 | J12: MANUTENÇÃO → CLIENTE | K12: marcelo.ferreira | L12: PONTA GROSSA | M12: CLIENTE | N12: DE LOJA PARA CLIENTE | O12: MPA | P12: https://maps.app.goo.gl/pQZUg9LPg5sgdyLs8 | Q12: GABRIEL - 42 -99972-7464 | R12: =IF( OR( IFERROR(FIND("BM",G12),0)>0, IFERROR(FIND("PY",G12),0)>0 ), MID(TRIM(SUBSTITUTE(SUBSTITUTE(G12,CHAR(160),""),CHAR(9),"")),4,5), MID(TRIM(SUBSTITUTE(SUBSTITUTE(G12,CHAR(160),""),CHAR(9),"")),4,4) ) -> 7215C | S12: {=_xlfn.LET( _xlpm.ch, TRIM(SUBSTITUTE(G12,CHAR(160),"")), _xlpm.ehTrator, OR(IFERROR(FIND("BM",_xlpm.ch),0)>0, IFERROR(FIND("PY",_xlpm.ch),0)>0), _xlpm.chave, IF(_xlpm.ehTrator, MID(_xlpm.ch,4,5), MID(_xlpm.ch,4,4)), _xlpm.fonte, IF(LEN(_xlpm.chave)=5, UTIL!BV:BV, UTIL!BU:BU), _xlpm.modelo, TRIM(SUBSTITUTE(R12,CHAR(160),"")), _xlpm.nomeMod, IFERROR(_xlfn.XLOOKUP("*"&_xlpm.modelo&"*", UTIL!D:D, UTIL!B:B, "", 2), IFERROR(_xlfn.XLOOKUP("*"&_xlpm.modelo&"*", UTIL!E:E, UTIL!B:B, "", 2), "")), _xlpm.tipoMod, IF(_xlpm.nomeMod="", "", IFERROR(LEFT(_xlpm.nomeMod, FIND(" ", _xlpm.nomeMod)-1), _xlpm.nomeMod)), _xlpm.dimMod, IFERROR(_xlfn.XLOOKUP("*"&_xlpm.modelo&"*", UTIL!D:D, UTIL!K:K, "", 2), IFERROR(_xlfn.XLOOKUP("*"&_xlpm.modelo&"*", UTIL!E:E, UTIL!K:K, "", 2), "")), _xlpm.tipotxt_antigo, IF(_xlpm.ehTrator, "TRATOR", IFERROR(_xlfn.XLOOKUP(_xlpm.chave, _xlpm.fonte, UTIL!BS:BS, "", 0), IFERROR(_xlfn.XLOOKUP("*"&_xlpm.chave&"*", _xlpm.fonte, UTIL!BS:BS, "", 2), "Não encontrado"))), _xlpm.dimtxt_antigo, IFERROR(_xlfn.XLOOKUP(_xlpm.chave, _xlpm.fonte, UTIL!CB:CB, "", 0), IFERROR(_xlfn.XLOOKUP("*"&_xlpm.chave&"*", _xlpm.fonte, UTIL!CB:CB, "", 2), "Não encontrado")), _xlpm.tipotxt, IF(_xlpm.tipoMod<>"", _xlpm.tipoMod, _xlpm.tipotxt_antigo), _xlpm.dimtxt, IF(_xlpm.dimMod<>"", _xlpm.dimMod, _xlpm.dimtxt_antigo), _xlpm.deTxt, IF(L12="CLIENTE", O12, IF(LEFT(L12,4)="http", L12, "MACPONTA AGRO DE "&L12)), _xlpm.paraBase, IF(M12="CLIENTE", P12, M12), _xlpm.paraTxt, IF(LEFT(_xlpm.paraBase,4)="http", _xlpm.paraBase, "MACPONTA AGRO DE "&_xlpm.paraBase), _xlpm.nfParte, IF(LEN(TRIM(I12))=0, "", " -NF "&TRIM(I12)), "- " & _xlpm.tipotxt & ": *" & G12 & "*" & CHAR(13)&CHAR(10) & "- " & _xlpm.dimtxt & CHAR(13)&CHAR(10) & "- *Cliente*: " & J12 & _xlpm.nfParte & CHAR(13)&CHAR(10) & "- *Obs:* " & Q12 & CHAR(13)&CHAR(10) & CHAR(10) & "- *De*: " & _xlpm.deTxt & CHAR(13)&CHAR(10) & "- *Para*: " & _xlpm.paraTxt & CHAR(13)&CHAR(10) & "- *Ida e volta*: +/- " & TEXT(((D12*1.5)/1440),"h:mm") & "h | " & D12 & "km" )} -> - TRATOR: *1BM7215CVR3000057*_x000D_ - _x000D_ - *Cliente*: MANUTENÇÃO → CLIENTE -NF 45967_x000D_ - *Obs:* GABRIEL - 42 -99972-7464_x000D_ - *De*: MACPONTA AGRO DE PONTA GROSSA_x000D_ - *Para*: https://maps.app.goo.gl/pQZUg9LPg5sgdyLs8_x000D_ - *Ida e volta*: +/- 1:16h | 51km
A13: CONCLUIDO | B13: PROPRIO VW | C13: 0.022916667 | D13: 22 | E13: =IFERROR((D13*7),"?") -> 154 | F13: 0 | G13: 1P06110DABA021136 | H13: 45966 | I13: 45967 | J13: MANUTENÇÃO → CLIENTE | K13: leonardo.ramos | L13: PONTA GROSSA | M13: CLIENTE | N13: DE LOJA PARA CLIENTE | O13: MPA | P13: https://maps.app.goo.gl/zzmzdRt4m8WXMVjg9 | Q13: JUNIOR +55 42 8866-3271 | R13: =IF( OR( IFERROR(FIND("BM",G13),0)>0, IFERROR(FIND("PY",G13),0)>0 ), MID(TRIM(SUBSTITUTE(SUBSTITUTE(G13,CHAR(160),""),CHAR(9),"")),4,5), MID(TRIM(SUBSTITUTE(SUBSTITUTE(G13,CHAR(160),""),CHAR(9),"")),4,4) ) -> 6110 | S13: {=_xlfn.LET( _xlpm.ch, TRIM(SUBSTITUTE(G13,CHAR(160),"")), _xlpm.ehTrator, OR(IFERROR(FIND("BM",_xlpm.ch),0)>0, IFERROR(FIND("PY",_xlpm.ch),0)>0), _xlpm.chave, IF(_xlpm.ehTrator, MID(_xlpm.ch,4,5), MID(_xlpm.ch,4,4)), _xlpm.fonte, IF(LEN(_xlpm.chave)=5, UTIL!BV:BV, UTIL!BU:BU), _xlpm.modelo, TRIM(SUBSTITUTE(R13,CHAR(160),"")), _xlpm.nomeMod, IFERROR(_xlfn.XLOOKUP("*"&_xlpm.modelo&"*", UTIL!D:D, UTIL!B:B, "", 2), IFERROR(_xlfn.XLOOKUP("*"&_xlpm.modelo&"*", UTIL!E:E, UTIL!B:B, "", 2), "")), _xlpm.tipoMod, IF(_xlpm.nomeMod="", "", IFERROR(LEFT(_xlpm.nomeMod, FIND(" ", _xlpm.nomeMod)-1), _xlpm.nomeMod)), _xlpm.dimMod, IFERROR(_xlfn.XLOOKUP("*"&_xlpm.modelo&"*", UTIL!D:D, UTIL!K:K, "", 2), IFERROR(_xlfn.XLOOKUP("*"&_xlpm.modelo&"*", UTIL!E:E, UTIL!K:K, "", 2), "")), _xlpm.tipotxt_antigo, IF(_xlpm.ehTrator, "TRATOR", IFERROR(_xlfn.XLOOKUP(_xlpm.chave, _xlpm.fonte, UTIL!BS:BS, "", 0), IFERROR(_xlfn.XLOOKUP("*"&_xlpm.chave&"*", _xlpm.fonte, UTIL!BS:BS, "", 2), "Não encontrado"))), _xlpm.dimtxt_antigo, IFERROR(_xlfn.XLOOKUP(_xlpm.chave, _xlpm.fonte, UTIL!CB:CB, "", 0), IFERROR(_xlfn.XLOOKUP("*"&_xlpm.chave&"*", _xlpm.fonte, UTIL!CB:CB, "", 2), "Não encontrado")), _xlpm.tipotxt, IF(_xlpm.tipoMod<>"", _xlpm.tipoMod, _xlpm.tipotxt_antigo), _xlpm.dimtxt, IF(_xlpm.dimMod<>"", _xlpm.dimMod, _xlpm.dimtxt_antigo), _xlpm.deTxt, IF(L13="CLIENTE", O13, IF(LEFT(L13,4)="http", L13, "MACPONTA AGRO DE "&L13)), _xlpm.paraBase, IF(M13="CLIENTE", P13, M13), _xlpm.paraTxt, IF(LEFT(_xlpm.paraBase,4)="http", _xlpm.paraBase, "MACPONTA AGRO DE "&_xlpm.paraBase), _xlpm.nfParte, IF(LEN(TRIM(I13))=0, "", " -NF "&TRIM(I13)), "- " & _xlpm.tipotxt & ": *" & G13 & "*" & CHAR(13)&CHAR(10) & "- " & _xlpm.dimtxt & CHAR(13)&CHAR(10) & "- *Cliente*: " & J13 & _xlpm.nfParte & CHAR(13)&CHAR(10) & "- *Obs:* " & Q13 & CHAR(13)&CHAR(10) & CHAR(10) & "- *De*: " & _xlpm.deTxt & CHAR(13)&CHAR(10) & "- *Para*: " & _xlpm.paraTxt & CHAR(13)&CHAR(10) & "- *Ida e volta*: +/- " & TEXT(((D13*1.5)/1440),"h:mm") & "h | " & D13 & "km" )} -> - : *1P06110DABA021136*_x000D_ - _x000D_ - *Cliente*: MANUTENÇÃO → CLIENTE -NF 45967_x000D_ - *Obs:* JUNIOR +55 42 8866-3271_x000D_ - *De*: MACPONTA AGRO DE PONTA GROSSA_x000D_ - *Para*: https://maps.app.goo.gl/zzmzdRt4m8WXMVjg9_x000D_ - *Ida e volta*: +/- 0:33h | 22km
... A20: CONCLUIDO | B20: PROPRIO DAF | C20: 0.18194444 | D20: 175 | E20: =IFERROR((D20*7),"?") -> 1225 | F20: 0 | G20: 1CQS680ATF0110209 | H20: 45968 | I20: 45969 | J20: DOUGLAS FANCHIN TAQUES FONSECA -NF278835 | K20: marcelo.ferreira | L20: PONTA GROSSA | M20: CLIENTE | N20: DE LOJA PARA CLIENTE | O20: MPA | P20: https://maps.app.goo.gl/GfTKV558G2iXHWmg8 | Q20: VALTINHO 42-99920-3056 | R20: =IF( OR( IFERROR(FIND("BM",G20),0)>0, IFERROR(FIND("PY",G20),0)>0 ), MID(TRIM(SUBSTITUTE(SUBSTITUTE(G20,CHAR(160),""),CHAR(9),"")),4,5), MID(TRIM(SUBSTITUTE(SUBSTITUTE(G20,CHAR(160),""),CHAR(9),"")),4,4) ) -> S680 | S20: {=_xlfn.LET( _xlpm.ch, TRIM(SUBSTITUTE(G20,CHAR(160),"")), _xlpm.ehTrator, OR(IFERROR(FIND("BM",_xlpm.ch),0)>0, IFERROR(FIND("PY",_xlpm.ch),0)>0), _xlpm.chave, IF(_xlpm.ehTrator, MID(_xlpm.ch,4,5), MID(_xlpm.ch,4,4)), _xlpm.fonte, IF(LEN(_xlpm.chave)=5, UTIL!BV:BV, UTIL!BU:BU), _xlpm.modelo, TRIM(SUBSTITUTE(R20,CHAR(160),"")), _xlpm.nomeMod, IFERROR(_xlfn.XLOOKUP("*"&_xlpm.modelo&"*", UTIL!D:D, UTIL!B:B, "", 2), IFERROR(_xlfn.XLOOKUP("*"&_xlpm.modelo&"*", UTIL!E:E, UTIL!B:B, "", 2), "")), _xlpm.tipoMod, IF(_xlpm.nomeMod="", "", IFERROR(LEFT(_xlpm.nomeMod, FIND(" ", _xlpm.nomeMod)-1), _xlpm.nomeMod)), _xlpm.dimMod, IFERROR(_xlfn.XLOOKUP("*"&_xlpm.modelo&"*", UTIL!D:D, UTIL!K:K, "", 2), IFERROR(_xlfn.XLOOKUP("*"&_xlpm.modelo&"*", UTIL!E:E, UTIL!K:K, "", 2), "")), _xlpm.tipotxt_antigo, IF(_xlpm.ehTrator, "TRATOR", IFERROR(_xlfn.XLOOKUP(_xlpm.chave, _xlpm.fonte, UTIL!BS:BS, "", 0), IFERROR(_xlfn.XLOOKUP("*"&_xlpm.chave&"*", _xlpm.fonte, UTIL!BS:BS, "", 2), "Não encontrado"))), _xlpm.dimtxt_antigo, IFERROR(_xlfn.XLOOKUP(_xlpm.chave, _xlpm.fonte, UTIL!CB:CB, "", 0), IFERROR(_xlfn.XLOOKUP("*"&_xlpm.chave&"*", _xlpm.fonte, UTIL!CB:CB, "", 2), "Não encontrado")), _xlpm.tipotxt, IF(_xlpm.tipoMod<>"", _xlpm.tipoMod, _xlpm.tipotxt_antigo), _xlpm.dimtxt, IF(_xlpm.dimMod<>"", _xlpm.dimMod, _xlpm.dimtxt_antigo), _xlpm.deTxt, IF(L20="CLIENTE", O20, IF(LEFT(L20,4)="http", L20, "MACPONTA AGRO DE "&L20)), _xlpm.paraBase, IF(M20="CLIENTE", P20, M20), _xlpm.paraTxt, IF(LEFT(_xlpm.paraBase,4)="http", _xlpm.paraBase, "MACPONTA AGRO DE "&_xlpm.paraBase), _xlpm.nfParte, IF(LEN(TRIM(I20))=0, "", " -NF "&TRIM(I20)), "- " & _xlpm.tipotxt & ": *" & G20 & "*" & CHAR(13)&CHAR(10) & "- " & _xlpm.dimtxt & CHAR(13)&CHAR(10) & "- *Cliente*: " & J20 & _xlpm.nfParte & CHAR(13)&CHAR(10) & "- *Obs:* " & Q20 & CHAR(13)&CHAR(10) & CHAR(10) & "- *De*: " & _xlpm.deTxt & CHAR(13)&CHAR(10) & "- *Para*: " & _xlpm.paraTxt & CHAR(13)&CHAR(10) & "- *Ida e volta*: +/- " & TEXT(((D20*1.5)/1440),"h:mm") & "h | " & D20 & "km" )} -> - COLHEITADEIRA: *1CQS680ATF0110209*_x000D_ - A:3,98 x C:12,10 x L:3,50-5,43 x P:21.921kg_x000D_ - *Cliente*: DOUGLAS FANCHIN TAQUES FONSECA -NF278835 -NF 45969_x000D_ - *Obs:* VALTINHO 42-99920-3056_x000D_ - *De*: MACPONTA AGRO DE PONTA GROSSA_x000D_ - *Para*: https://maps.app.goo.gl/GfTKV558G2iXHWmg8_x000D_ - *Ida e volta*: +/- 4:22h | 175km
A21: CONCLUIDO | B21: TERCEIRO MAZETTO | C21: 0.34375 | D21: 330 | E21: =IFERROR((D21*7),"?") -> 2310 | G21: 1BM6100JVSD602522 | H21: 45968 | I21: 45968 | J21: ADILSON KRASSOSKI -NF11620 | K21: euclides.junior | L21: GUARAPUAVA | M21: CLIENTE | N21: DE LOJA PARA CLIENTE | O21: MPA | P21: https://maps.app.goo.gl/nUnfbBeivgDPDFmy6 | Q21: Adilson | R21: =IF( OR( IFERROR(FIND("BM",G21),0)>0, IFERROR(FIND("PY",G21),0)>0 ), MID(TRIM(SUBSTITUTE(SUBSTITUTE(G21,CHAR(160),""),CHAR(9),"")),4,5), MID(TRIM(SUBSTITUTE(SUBSTITUTE(G21,CHAR(160),""),CHAR(9),"")),4,4) ) -> 6100J | S21: {=_xlfn.LET( _xlpm.ch, TRIM(SUBSTITUTE(G21,CHAR(160),"")), _xlpm.ehTrator, OR(IFERROR(FIND("BM",_xlpm.ch),0)>0, IFERROR(FIND("PY",_xlpm.ch),0)>0), _xlpm.chave, IF(_xlpm.ehTrator, MID(_xlpm.ch,4,5), MID(_xlpm.ch,4,4)), _xlpm.fonte, IF(LEN(_xlpm.chave)=5, UTIL!BV:BV, UTIL!BU:BU), _xlpm.modelo, TRIM(SUBSTITUTE(R21,CHAR(160),"")), _xlpm.nomeMod, IFERROR(_xlfn.XLOOKUP("*"&_xlpm.modelo&"*", UTIL!D:D, UTIL!B:B, "", 2), IFERROR(_xlfn.XLOOKUP("*"&_xlpm.modelo&"*", UTIL!E:E, UTIL!B:B, "", 2), "")), _xlpm.tipoMod, IF(_xlpm.nomeMod="", "", IFERROR(LEFT(_xlpm.nomeMod, FIND(" ", _xlpm.nomeMod)-1), _xlpm.nomeMod)), _xlpm.dimMod, IFERROR(_xlfn.XLOOKUP("*"&_xlpm.modelo&"*", UTIL!D:D, UTIL!K:K, "", 2), IFERROR(_xlfn.XLOOKUP("*"&_xlpm.modelo&"*", UTIL!E:E, UTIL!K:K, "", 2), "")), _xlpm.tipotxt_antigo, IF(_xlpm.ehTrator, "TRATOR", IFERROR(_xlfn.XLOOKUP(_xlpm.chave, _xlpm.fonte, UTIL!BS:BS, "", 0), IFERROR(_xlfn.XLOOKUP("*"&_xlpm.chave&"*", _xlpm.fonte, UTIL!BS:BS, "", 2), "Não encontrado"))), _xlpm.dimtxt_antigo, IFERROR(_xlfn.XLOOKUP(_xlpm.chave, _xlpm.fonte, UTIL!CB:CB, "", 0), IFERROR(_xlfn.XLOOKUP("*"&_xlpm.chave&"*", _xlpm.fonte, UTIL!CB:CB, "", 2), "Não encontrado")), _xlpm.tipotxt, IF(_xlpm.tipoMod<>"", _xlpm.tipoMod, _xlpm.tipotxt_antigo), _xlpm.dimtxt, IF(_xlpm.dimMod<>"", _xlpm.dimMod, _xlpm.dimtxt_antigo), _xlpm.deTxt, IF(L21="CLIENTE", O21, IF(LEFT(L21,4)="http", L21, "MACPONTA AGRO DE "&L21)), _xlpm.paraBase, IF(M21="CLIENTE", P21, M21), _xlpm.paraTxt, IF(LEFT(_xlpm.paraBase,4)="http", _xlpm.paraBase, "MACPONTA AGRO DE "&_xlpm.paraBase), _xlpm.nfParte, IF(LEN(TRIM(I21))=0, "", " -NF "&TRIM(I21)), "- " & _xlpm.tipotxt & ": *" & G21 & "*" & CHAR(13)&CHAR(10) & "- " & _xlpm.dimtxt & CHAR(13)&CHAR(10) & "- *Cliente*: " & J21 & _xlpm.nfParte & CHAR(13)&CHAR(10) & "- *Obs:* " & Q21 & CHAR(13)&CHAR(10) & CHAR(10) & "- *De*: " & _xlpm.deTxt & CHAR(13)&CHAR(10) & "- *Para*: " & _xlpm.paraTxt & CHAR(13)&CHAR(10) & "- *Ida e volta*: +/- " & TEXT(((D21*1.5)/1440),"h:mm") & "h | " & D21 & "km" )} -> - TRATOR: *1BM6100JVSD602522*_x000D_ - _x000D_ - *Cliente*: ADILSON KRASSOSKI -NF11620 -NF 45968_x000D_ - *Obs:* Adilson_x000D_ - *De*: MACPONTA AGRO DE GUARAPUAVA_x000D_ - *Para*: https://maps.app.goo.gl/nUnfbBeivgDPDFmy6_x000D_ - *Ida e volta*: +/- 8:15h | 330km
A22: CONCLUIDO | B22: PROPRIO DAF | C22: 0.33819444 | D22: 325 | E22: =IFERROR((D22*7),"?") -> 2275 | F22: 0 | G22: 9AGC1007EHS000187 | H22: 45972 | I22: 45972 | J22: TRANSF -NF000076891 | K22: marcio.jacovossi | L22: IRATI | M22: PRUDENTÓPOLIS | N22: DE LOJA PARA LOJA | O22: MPA | P22: MPA | Q22: N/A | R22: =IF( OR( IFERROR(FIND("BM",G22),0)>0, IFERROR(FIND("PY",G22),0)>0 ), MID(TRIM(SUBSTITUTE(SUBSTITUTE(G22,CHAR(160),""),CHAR(9),"")),4,5), MID(TRIM(SUBSTITUTE(SUBSTITUTE(G22,CHAR(160),""),CHAR(9),"")),4,4) ) -> C100 | S22: {=_xlfn.LET( _xlpm.ch, TRIM(SUBSTITUTE(G22,CHAR(160),"")), _xlpm.ehTrator, OR(IFERROR(FIND("BM",_xlpm.ch),0)>0, IFERROR(FIND("PY",_xlpm.ch),0)>0), _xlpm.chave, IF(_xlpm.ehTrator, MID(_xlpm.ch,4,5), MID(_xlpm.ch,4,4)), _xlpm.fonte, IF(LEN(_xlpm.chave)=5, UTIL!BV:BV, UTIL!BU:BU), _xlpm.modelo, TRIM(SUBSTITUTE(R22,CHAR(160),"")), _xlpm.nomeMod, IFERROR(_xlfn.XLOOKUP("*"&_xlpm.modelo&"*", UTIL!D:D, UTIL!B:B, "", 2), IFERROR(_xlfn.XLOOKUP("*"&_xlpm.modelo&"*", UTIL!E:E, UTIL!B:B, "", 2), "")), _xlpm.tipoMod, IF(_xlpm.nomeMod="", "", IFERROR(LEFT(_xlpm.nomeMod, FIND(" ", _xlpm.nomeMod)-1), _xlpm.nomeMod)), _xlpm.dimMod, IFERROR(_xlfn.XLOOKUP("*"&_xlpm.modelo&"*", UTIL!D:D, UTIL!K:K, "", 2), IFERROR(_xlfn.XLOOKUP("*"&_xlpm.modelo&"*", UTIL!E:E, UTIL!K:K, "", 2), "")), _xlpm.tipotxt_antigo, IF(_xlpm.ehTrator, "TRATOR", IFERROR(_xlfn.XLOOKUP(_xlpm.chave, _xlpm.fonte, UTIL!BS:BS, "", 0), IFERROR(_xlfn.XLOOKUP("*"&_xlpm.chave&"*", _xlpm.fonte, UTIL!BS:BS, "", 2), "Não encontrado"))), _xlpm.dimtxt_antigo, IFERROR(_xlfn.XLOOKUP(_xlpm.chave, _xlpm.fonte, UTIL!CB:CB, "", 0), IFERROR(_xlfn.XLOOKUP("*"&_xlpm.chave&"*", _xlpm.fonte, UTIL!CB:CB, "", 2), "Não encontrado")), _xlpm.tipotxt, IF(_xlpm.tipoMod<>"", _xlpm.tipoMod, _xlpm.tipotxt_antigo), _xlpm.dimtxt, IF(_xlpm.dimMod<>"", _xlpm.dimMod, _xlpm.dimtxt_antigo), _xlpm.deTxt, IF(L22="CLIENTE", O22, IF(LEFT(L22,4)="http", L22, "MACPONTA AGRO DE "&L22)), _xlpm.paraBase, IF(M22="CLIENTE", P22, M22), _xlpm.paraTxt, IF(LEFT(_xlpm.paraBase,4)="http", _xlpm.paraBase, "MACPONTA AGRO DE "&_xlpm.paraBase), _xlpm.nfParte, IF(LEN(TRIM(I22))=0, "", " -NF "&TRIM(I22)), "- " & _xlpm.tipotxt & ": *" & G22 & "*" & CHAR(13)&CHAR(10) & "- " & _xlpm.dimtxt & CHAR(13)&CHAR(10) & "- *Cliente*: " & J22 & _xlpm.nfParte & CHAR(13)&CHAR(10) & "- *Obs:* " & Q22 & CHAR(13)&CHAR(10) & CHAR(10) & "- *De*: " & _xlpm.deTxt & CHAR(13)&CHAR(10) & "- *Para*: " & _xlpm.paraTxt & CHAR(13)&CHAR(10) & "- *Ida e volta*: +/- " & TEXT(((D22*1.5)/1440),"h:mm") & "h | " & D22 & "km" )} -> - : *9AGC1007EHS000187*_x000D_ - _x000D_ - *Cliente*: TRANSF -NF000076891 -NF 45972_x000D_ - *Obs:* N/A_x000D_ - *De*: MACPONTA AGRO DE IRATI_x000D_ - *Para*: MACPONTA AGRO DE PRUDENTÓPOLIS_x000D_ - *Ida e volta*: +/- 8:07h | 325km
A23: CONCLUIDO | B23: PROPRIO DAF | C23: 0.33819444 | D23: 325 | E23: =IFERROR((D23*7),"?") -> 2275 | F23: 0 | G23: AAAP1112CGS000944 | H23: 45972 | I23: 45972 | J23: TRANSF -NF000076886 | K23: marcio.jacovossi | L23: IRATI | M23: PRUDENTÓPOLIS | N23: DE LOJA PARA LOJA | O23: MPA | P23: MPA | Q23: N/A | R23: =IF( OR( IFERROR(FIND("BM",G23),0)>0, IFERROR(FIND("PY",G23),0)>0 ), MID(TRIM(SUBSTITUTE(SUBSTITUTE(G23,CHAR(160),""),CHAR(9),"")),4,5), MID(TRIM(SUBSTITUTE(SUBSTITUTE(G23,CHAR(160),""),CHAR(9),"")),4,4) ) -> P111 | S23: {=_xlfn.LET( _xlpm.ch, TRIM(SUBSTITUTE(G23,CHAR(160),"")), _xlpm.ehTrator, OR(IFERROR(FIND("BM",_xlpm.ch),0)>0, IFERROR(FIND("PY",_xlpm.ch),0)>0), _xlpm.chave, IF(_xlpm.ehTrator, MID(_xlpm.ch,4,5), MID(_xlpm.ch,4,4)), _xlpm.fonte, IF(LEN(_xlpm.chave)=5, UTIL!BV:BV, UTIL!BU:BU), _xlpm.modelo, TRIM(SUBSTITUTE(R23,CHAR(160),"")), _xlpm.nomeMod, IFERROR(_xlfn.XLOOKUP("*"&_xlpm.modelo&"*", UTIL!D:D, UTIL!B:B, "", 2), IFERROR(_xlfn.XLOOKUP("*"&_xlpm.modelo&"*", UTIL!E:E, UTIL!B:B, "", 2), "")), _xlpm.tipoMod, IF(_xlpm.nomeMod="", "", IFERROR(LEFT(_xlpm.nomeMod, FIND(" ", _xlpm.nomeMod)-1), _xlpm.nomeMod)), _xlpm.dimMod, IFERROR(_xlfn.XLOOKUP("*"&_xlpm.modelo&"*", UTIL!D:D, UTIL!K:K, "", 2), IFERROR(_xlfn.XLOOKUP("*"&_xlpm.modelo&"*", UTIL!E:E, UTIL!K:K, "", 2), "")), _xlpm.tipotxt_antigo, IF(_xlpm.ehTrator, "TRATOR", IFERROR(_xlfn.XLOOKUP(_xlpm.chave, _xlpm.fonte, UTIL!BS:BS, "", 0), IFERROR(_xlfn.XLOOKUP("*"&_xlpm.chave&"*", _xlpm.fonte, UTIL!BS:BS, "", 2), "Não encontrado"))), _xlpm.dimtxt_antigo, IFERROR(_xlfn.XLOOKUP(_xlpm.chave, _xlpm.fonte, UTIL!CB:CB, "", 0), IFERROR(_xlfn.XLOOKUP("*"&_xlpm.chave&"*", _xlpm.fonte, UTIL!CB:CB, "", 2), "Não encontrado")), _xlpm.tipotxt, IF(_xlpm.tipoMod<>"", _xlpm.tipoMod, _xlpm.tipotxt_antigo), _xlpm.dimtxt, IF(_xlpm.dimMod<>"", _xlpm.dimMod, _xlpm.dimtxt_antigo), _xlpm.deTxt, IF(L23="CLIENTE", O23, IF(LEFT(L23,4)="http", L23, "MACPONTA AGRO DE "&L23)), _xlpm.paraBase, IF(M23="CLIENTE", P23, M23), _xlpm.paraTxt, IF(LEFT(_xlpm.paraBase,4)="http", _xlpm.paraBase, "MACPONTA AGRO DE "&_xlpm.paraBase), _xlpm.nfParte, IF(LEN(TRIM(I23))=0, "", " -NF "&TRIM(I23)), "- " & _xlpm.tipotxt & ": *" & G23 & "*" & CHAR(13)&CHAR(10) & "- " & _xlpm.dimtxt & CHAR(13)&CHAR(10) & "- *Cliente*: " & J23 & _xlpm.nfParte & CHAR(13)&CHAR(10) & "- *Obs:* " & Q23 & CHAR(13)&CHAR(10) & CHAR(10) & "- *De*: " & _xlpm.deTxt & CHAR(13)&CHAR(10) & "- *Para*: " & _xlpm.paraTxt & CHAR(13)&CHAR(10) & "- *Ida e volta*: +/- " & TEXT(((D23*1.5)/1440),"h:mm") & "h | " & D23 & "km" )} -> - : *AAAP1112CGS000944*_x000D_ - _x000D_ - *Cliente*: TRANSF -NF000076886 -NF 45972_x000D_ - *Obs:* N/A_x000D_ - *De*: MACPONTA AGRO DE IRATI_x000D_ - *Para*: MACPONTA AGRO DE PRUDENTÓPOLIS_x000D_ - *Ida e volta*: +/- 8:07h | 325km
A24: CONCLUIDO | B24: PROPRIO DAF | C24: 0.26527778 | D24: 255 | E24: =IFERROR((D24*7),"?") -> 1785 | F24: 0 | G24: 1BM6150JCSD642412 | H24: 45972 | I24: 45972 | J24: TRANSF -NF000076884 | K24: marcio.jacovossi | L24: IRATI | M24: PRUDENTÓPOLIS | N24: DE LOJA PARA LOJA | O24: MPA | P24: MPA | Q24: N/A | R24: =IF( OR( IFERROR(FIND("BM",G24),0)>0, IFERROR(FIND("PY",G24),0)>0 ), MID(TRIM(SUBSTITUTE(SUBSTITUTE(G24,CHAR(160),""),CHAR(9),"")),4,5), MID(TRIM(SUBSTITUTE(SUBSTITUTE(G24,CHAR(160),""),CHAR(9),"")),4,4) ) -> 6150J | S24: {=_xlfn.LET( _xlpm.ch, TRIM(SUBSTITUTE(G24,CHAR(160),"")), _xlpm.ehTrator, OR(IFERROR(FIND("BM",_xlpm.ch),0)>0, IFERROR(FIND("PY",_xlpm.ch),0)>0), _xlpm.chave, IF(_xlpm.ehTrator, MID(_xlpm.ch,4,5), MID(_xlpm.ch,4,4)), _xlpm.fonte, IF(LEN(_xlpm.chave)=5, UTIL!BV:BV, UTIL!BU:BU), _xlpm.modelo, TRIM(SUBSTITUTE(R24,CHAR(160),"")), _xlpm.nomeMod, IFERROR(_xlfn.XLOOKUP("*"&_xlpm.modelo&"*", UTIL!D:D, UTIL!B:B, "", 2), IFERROR(_xlfn.XLOOKUP("*"&_xlpm.modelo&"*", UTIL!E:E, UTIL!B:B, "", 2), "")), _xlpm.tipoMod, IF(_xlpm.nomeMod="", "", IFERROR(LEFT(_xlpm.nomeMod, FIND(" ", _xlpm.nomeMod)-1), _xlpm.nomeMod)), _xlpm.dimMod, IFERROR(_xlfn.XLOOKUP("*"&_xlpm.modelo&"*", UTIL!D:D, UTIL!K:K, "", 2), IFERROR(_xlfn.XLOOKUP("*"&_xlpm.modelo&"*", UTIL!E:E, UTIL!K:K, "", 2), "")), _xlpm.tipotxt_antigo, IF(_xlpm.ehTrator, "TRATOR", IFERROR(_xlfn.XLOOKUP(_xlpm.chave, _xlpm.fonte, UTIL!BS:BS, "", 0), IFERROR(_xlfn.XLOOKUP("*"&_xlpm.chave&"*", _xlpm.fonte, UTIL!BS:BS, "", 2), "Não encontrado"))), _xlpm.dimtxt_antigo, IFERROR(_xlfn.XLOOKUP(_xlpm.chave, _xlpm.fonte, UTIL!CB:CB, "", 0), IFERROR(_xlfn.XLOOKUP("*"&_xlpm.chave&"*", _xlpm.fonte, UTIL!CB:CB, "", 2), "Não encontrado")), _xlpm.tipotxt, IF(_xlpm.tipoMod<>"", _xlpm.tipoMod, _xlpm.tipotxt_antigo), _xlpm.dimtxt, IF(_xlpm.dimMod<>"", _xlpm.dimMod, _xlpm.dimtxt_antigo), _xlpm.deTxt, IF(L24="CLIENTE", O24, IF(LEFT(L24,4)="http", L24, "MACPONTA AGRO DE "&L24)), _xlpm.paraBase, IF(M24="CLIENTE", P24, M24), _xlpm.paraTxt, IF(LEFT(_xlpm.paraBase,4)="http", _xlpm.paraBase, "MACPONTA AGRO DE "&_xlpm.paraBase), _xlpm.nfParte, IF(LEN(TRIM(I24))=0, "", " -NF "&TRIM(I24)), "- " & _xlpm.tipotxt & ": *" & G24 & "*" & CHAR(13)&CHAR(10) & "- " & _xlpm.dimtxt & CHAR(13)&CHAR(10) & "- *Cliente*: " & J24 & _xlpm.nfParte & CHAR(13)&CHAR(10) & "- *Obs:* " & Q24 & CHAR(13)&CHAR(10) & CHAR(10) & "- *De*: " & _xlpm.deTxt & CHAR(13)&CHAR(10) & "- *Para*: " & _xlpm.paraTxt & CHAR(13)&CHAR(10) & "- *Ida e volta*: +/- " & TEXT(((D24*1.5)/1440),"h:mm") & "h | " & D24 & "km" )} -> - TRATOR: *1BM6150JCSD642412*_x000D_ - _x000D_ - *Cliente*: TRANSF -NF000076884 -NF 45972_x000D_ - *Obs:* N/A_x000D_ - *De*: MACPONTA AGRO DE IRATI_x000D_ - *Para*: MACPONTA AGRO DE PRUDENTÓPOLIS_x000D_ - *Ida e volta*: +/- 6:22h | 255km
A25: CONCLUIDO | B25: PROPRIO DAF | C25: 0.26527778 | D25: 255 | E25: =IFERROR((D25*7),"?") -> 1785 | F25: 0 | G25: 1BM5078EHS4200616 | H25: 45972 | I25: 45972 | J25: TRANSF -NF000076884 | K25: marcio.jacovossi | L25: IRATI | M25: PRUDENTÓPOLIS | N25: DE LOJA PARA LOJA | O25: MPA | P25: MPA | Q25: N/A | R25: =IF( OR( IFERROR(FIND("BM",G25),0)>0, IFERROR(FIND("PY",G25),0)>0 ), MID(TRIM(SUBSTITUTE(SUBSTITUTE(G25,CHAR(160),""),CHAR(9),"")),4,5), MID(TRIM(SUBSTITUTE(SUBSTITUTE(G25,CHAR(160),""),CHAR(9),"")),4,4) ) -> 5078E | S25: {=_xlfn.LET( _xlpm.ch, TRIM(SUBSTITUTE(G25,CHAR(160),"")), _xlpm.ehTrator, OR(IFERROR(FIND("BM",_xlpm.ch),0)>0, IFERROR(FIND("PY",_xlpm.ch),0)>0), _xlpm.chave, IF(_xlpm.ehTrator, MID(_xlpm.ch,4,5), MID(_xlpm.ch,4,4)), _xlpm.fonte, IF(LEN(_xlpm.chave)=5, UTIL!BV:BV, UTIL!BU:BU), _xlpm.modelo, TRIM(SUBSTITUTE(R25,CHAR(160),"")), _xlpm.nomeMod, IFERROR(_xlfn.XLOOKUP("*"&_xlpm.modelo&"*", UTIL!D:D, UTIL!B:B, "", 2), IFERROR(_xlfn.XLOOKUP("*"&_xlpm.modelo&"*", UTIL!E:E, UTIL!B:B, "", 2), "")), _xlpm.tipoMod, IF(_xlpm.nomeMod="", "", IFERROR(LEFT(_xlpm.nomeMod, FIND(" ", _xlpm.nomeMod)-1), _xlpm.nomeMod)), _xlpm.dimMod, IFERROR(_xlfn.XLOOKUP("*"&_xlpm.modelo&"*", UTIL!D:D, UTIL!K:K, "", 2), IFERROR(_xlfn.XLOOKUP("*"&_xlpm.modelo&"*", UTIL!E:E, UTIL!K:K, "", 2), "")), _xlpm.tipotxt_antigo, IF(_xlpm.ehTrator, "TRATOR", IFERROR(_xlfn.XLOOKUP(_xlpm.chave, _xlpm.fonte, UTIL!BS:BS, "", 0), IFERROR(_xlfn.XLOOKUP("*"&_xlpm.chave&"*", _xlpm.fonte, UTIL!BS:BS, "", 2), "Não encontrado"))), _xlpm.dimtxt_antigo, IFERROR(_xlfn.XLOOKUP(_xlpm.chave, _xlpm.fonte, UTIL!CB:CB, "", 0), IFERROR(_xlfn.XLOOKUP("*"&_xlpm.chave&"*", _xlpm.fonte, UTIL!CB:CB, "", 2), "Não encontrado")), _xlpm.tipotxt, IF(_xlpm.tipoMod<>"", _xlpm.tipoMod, _xlpm.tipotxt_antigo), _xlpm.dimtxt, IF(_xlpm.dimMod<>"", _xlpm.dimMod, _xlpm.dimtxt_antigo), _xlpm.deTxt, IF(L25="CLIENTE", O25, IF(LEFT(L25,4)="http", L25, "MACPONTA AGRO DE "&L25)), _xlpm.paraBase, IF(M25="CLIENTE", P25, M25), _xlpm.paraTxt, IF(LEFT(_xlpm.paraBase,4)="http", _xlpm.paraBase, "MACPONTA AGRO DE "&_xlpm.paraBase), _xlpm.nfParte, IF(LEN(TRIM(I25))=0, "", " -NF "&TRIM(I25)), "- " & _xlpm.tipotxt & ": *" & G25 & "*" & CHAR(13)&CHAR(10) & "- " & _xlpm.dimtxt & CHAR(13)&CHAR(10) & "- *Cliente*: " & J25 & _xlpm.nfParte & CHAR(13)&CHAR(10) & "- *Obs:* " & Q25 & CHAR(13)&CHAR(10) & CHAR(10) & "- *De*: " & _xlpm.deTxt & CHAR(13)&CHAR(10) & "- *Para*: " & _xlpm.paraTxt & CHAR(13)&CHAR(10) & "- *Ida e volta*: +/- " & TEXT(((D25*1.5)/1440),"h:mm") & "h | " & D25 & "km" )} -> - TRATOR: *1BM5078EHS4200616*_x000D_ - _x000D_ - *Cliente*: TRANSF -NF000076884 -NF 45972_x000D_ - *Obs:* N/A_x000D_ - *De*: MACPONTA AGRO DE IRATI_x000D_ - *Para*: MACPONTA AGRO DE PRUDENTÓPOLIS_x000D_ - *Ida e volta*: +/- 6:22h | 255km
A26: CONCLUIDO | B26: TERCEIRO MAZETTO | C26: 0.08125 | D26: 78 | E26: =IFERROR((D26*7),"?") -> 546 | G26: 1BM6100JESD602123 | H26: 45972 | I26: 45972 | J26: OSWALDO R BARBOSA -NF107698 | K26: euclides.junior | L26: PRUDENTÓPOLIS | M26: CLIENTE | N26: DE LOJA PARA CLIENTE | O26: MPA | P26: https://maps.app.goo.gl/3mYP9KzrASogJS3w9 | Q26: Oswaldo | R26: =IF( OR( IFERROR(FIND("BM",G26),0)>0, IFERROR(FIND("PY",G26),0)>0 ), MID(TRIM(SUBSTITUTE(SUBSTITUTE(G26,CHAR(160),""),CHAR(9),"")),4,5), MID(TRIM(SUBSTITUTE(SUBSTITUTE(G26,CHAR(160),""),CHAR(9),"")),4,4) ) -> 6100J | S26: {=_xlfn.LET( _xlpm.ch, TRIM(SUBSTITUTE(G26,CHAR(160),"")), _xlpm.ehTrator, OR(IFERROR(FIND("BM",_xlpm.ch),0)>0, IFERROR(FIND("PY",_xlpm.ch),0)>0), _xlpm.chave, IF(_xlpm.ehTrator, MID(_xlpm.ch,4,5), MID(_xlpm.ch,4,4)), _xlpm.fonte, IF(LEN(_xlpm.chave)=5, UTIL!BV:BV, UTIL!BU:BU), _xlpm.modelo, TRIM(SUBSTITUTE(R26,CHAR(160),"")), _xlpm.nomeMod, IFERROR(_xlfn.XLOOKUP("*"&_xlpm.modelo&"*", UTIL!D:D, UTIL!B:B, "", 2), IFERROR(_xlfn.XLOOKUP("*"&_xlpm.modelo&"*", UTIL!E:E, UTIL!B:B, "", 2), "")), _xlpm.tipoMod, IF(_xlpm.nomeMod="", "", IFERROR(LEFT(_xlpm.nomeMod, FIND(" ", _xlpm.nomeMod)-1), _xlpm.nomeMod)), _xlpm.dimMod, IFERROR(_xlfn.XLOOKUP("*"&_xlpm.modelo&"*", UTIL!D:D, UTIL!K:K, "", 2), IFERROR(_xlfn.XLOOKUP("*"&_xlpm.modelo&"*", UTIL!E:E, UTIL!K:K, "", 2), "")), _xlpm.tipotxt_antigo, IF(_xlpm.ehTrator, "TRATOR", IFERROR(_xlfn.XLOOKUP(_xlpm.chave, _xlpm.fonte, UTIL!BS:BS, "", 0), IFERROR(_xlfn.XLOOKUP("*"&_xlpm.chave&"*", _xlpm.fonte, UTIL!BS:BS, "", 2), "Não encontrado"))), _xlpm.dimtxt_antigo, IFERROR(_xlfn.XLOOKUP(_xlpm.chave, _xlpm.fonte, UTIL!CB:CB, "", 0), IFERROR(_xlfn.XLOOKUP("*"&_xlpm.chave&"*", _xlpm.fonte, UTIL!CB:CB, "", 2), "Não encontrado")), _xlpm.tipotxt, IF(_xlpm.tipoMod<>"", _xlpm.tipoMod, _xlpm.tipotxt_antigo), _xlpm.dimtxt, IF(_xlpm.dimMod<>"", _xlpm.dimMod, _xlpm.dimtxt_antigo), _xlpm.deTxt, IF(L26="CLIENTE", O26, IF(LEFT(L26,4)="http", L26, "MACPONTA AGRO DE "&L26)), _xlpm.paraBase, IF(M26="CLIENTE", P26, M26), _xlpm.paraTxt, IF(LEFT(_xlpm.paraBase,4)="http", _xlpm.paraBase, "MACPONTA AGRO DE "&_xlpm.paraBase), _xlpm.nfParte, IF(LEN(TRIM(I26))=0, "", " -NF "&TRIM(I26)), "- " & _xlpm.tipotxt & ": *" & G26 & "*" & CHAR(13)&CHAR(10) & "- " & _xlpm.dimtxt & CHAR(13)&CHAR(10) & "- *Cliente*: " & J26 & _xlpm.nfParte & CHAR(13)&CHAR(10) & "- *Obs:* " & Q26 & CHAR(13)&CHAR(10) & CHAR(10) & "- *De*: " & _xlpm.deTxt & CHAR(13)&CHAR(10) & "- *Para*: " & _xlpm.paraTxt & CHAR(13)&CHAR(10) & "- *Ida e volta*: +/- " & TEXT(((D26*1.5)/1440),"h:mm") & "h | " & D26 & "km" )} -> - TRATOR: *1BM6100JESD602123*_x000D_ - _x000D_ - *Cliente*: OSWALDO R BARBOSA -NF107698 -NF 45972_x000D_ - *Obs:* Oswaldo_x000D_ - *De*: MACPONTA AGRO DE PRUDENTÓPOLIS_x000D_ - *Para*: https://maps.app.goo.gl/3mYP9KzrASogJS3w9_x000D_ - *Ida e volta*: +/- 1:57h | 78km
A27: CONCLUIDO (D) | B27: PROPRIO DAF | C27: 0.52083333 | D27: 500 | E27: =IFERROR((D27*7),"?") -> 3500 | F27: 0 | G27: 1CQS550APS0160136 | H27: 45972 | I27: 45971 | J27: DOUGLAS FONSECA -NF 107225 | K27: marcelo.ferreira | L27: GUARAPUAVA | M27: CLIENTE | N27: DE LOJA PARA DEMONSTRAÇÃO | O27: MPA | P27: https://maps.app.goo.gl/xyQpe8BG44WqsG1v9 | Q27: N/A | R27: =IF( OR( IFERROR(FIND("BM",G27),0)>0, IFERROR(FIND("PY",G27),0)>0 ), MID(TRIM(SUBSTITUTE(SUBSTITUTE(G27,CHAR(160),""),CHAR(9),"")),4,5), MID(TRIM(SUBSTITUTE(SUBSTITUTE(G27,CHAR(160),""),CHAR(9),"")),4,4) ) -> S550 | S27: {=_xlfn.LET( _xlpm.ch, TRIM(SUBSTITUTE(G27,CHAR(160),"")), _xlpm.ehTrator, OR(IFERROR(FIND("BM",_xlpm.ch),0)>0, IFERROR(FIND("PY",_xlpm.ch),0)>0), _xlpm.chave, IF(_xlpm.ehTrator, MID(_xlpm.ch,4,5), MID(_xlpm.ch,4,4)), _xlpm.fonte, IF(LEN(_xlpm.chave)=5, UTIL!BV:BV, UTIL!BU:BU), _xlpm.modelo, TRIM(SUBSTITUTE(R27,CHAR(160),"")), _xlpm.nomeMod, IFERROR(_xlfn.XLOOKUP("*"&_xlpm.modelo&"*", UTIL!D:D, UTIL!B:B, "", 2), IFERROR(_xlfn.XLOOKUP("*"&_xlpm.modelo&"*", UTIL!E:E, UTIL!B:B, "", 2), "")), _xlpm.tipoMod, IF(_xlpm.nomeMod="", "", IFERROR(LEFT(_xlpm.nomeMod, FIND(" ", _xlpm.nomeMod)-1), _xlpm.nomeMod)), _xlpm.dimMod, IFERROR(_xlfn.XLOOKUP("*"&_xlpm.modelo&"*", UTIL!D:D, UTIL!K:K, "", 2), IFERROR(_xlfn.XLOOKUP("*"&_xlpm.modelo&"*", UTIL!E:E, UTIL!K:K, "", 2), "")), _xlpm.tipotxt_antigo, IF(_xlpm.ehTrator, "TRATOR", IFERROR(_xlfn.XLOOKUP(_xlpm.chave, _xlpm.fonte, UTIL!BS:BS, "", 0), IFERROR(_xlfn.XLOOKUP("*"&_xlpm.chave&"*", _xlpm.fonte, UTIL!BS:BS, "", 2), "Não encontrado"))), _xlpm.dimtxt_antigo, IFERROR(_xlfn.XLOOKUP(_xlpm.chave, _xlpm.fonte, UTIL!CB:CB, "", 0), IFERROR(_xlfn.XLOOKUP("*"&_xlpm.chave&"*", _xlpm.fonte, UTIL!CB:CB, "", 2), "Não encontrado")), _xlpm.tipotxt, IF(_xlpm.tipoMod<>"", _xlpm.tipoMod, _xlpm.tipotxt_antigo), _xlpm.dimtxt, IF(_xlpm.dimMod<>"", _xlpm.dimMod, _xlpm.dimtxt_antigo), _xlpm.deTxt, IF(L27="CLIENTE", O27, IF(LEFT(L27,4)="http", L27, "MACPONTA AGRO DE "&L27)), _xlpm.paraBase, IF(M27="CLIENTE", P27, M27), _xlpm.paraTxt, IF(LEFT(_xlpm.paraBase,4)="http", _xlpm.paraBase, "MACPONTA AGRO DE "&_xlpm.paraBase), _xlpm.nfParte, IF(LEN(TRIM(I27))=0, "", " -NF "&TRIM(I27)), "- " & _xlpm.tipotxt & ": *" & G27 & "*" & CHAR(13)&CHAR(10) & "- " & _xlpm.dimtxt & CHAR(13)&CHAR(10) & "- *Cliente*: " & J27 & _xlpm.nfParte & CHAR(13)&CHAR(10) & "- *Obs:* " & Q27 & CHAR(13)&CHAR(10) & CHAR(10) & "- *De*: " & _xlpm.deTxt & CHAR(13)&CHAR(10) & "- *Para*: " & _xlpm.paraTxt & CHAR(13)&CHAR(10) & "- *Ida e volta*: +/- " & TEXT(((D27*1.5)/1440),"h:mm") & "h | " & D27 & "km" )} -> - COLHEITADEIRA: *1CQS550APS0160136*_x000D_ - A:3,80 x C:10,00 x L:3,70-4,20 x P:15.938kg_x000D_ - *Cliente*: DOUGLAS FONSECA -NF 107225 -NF 45971_x000D_ - *Obs:* N/A_x000D_ - *De*: MACPONTA AGRO DE GUARAPUAVA_x000D_ - *Para*: https://maps.app.goo.gl/xyQpe8BG44WqsG1v9_x000D_ - *Ida e volta*: +/- 12:30h | 500km
